Workbook

Sheet הנחות
A1: תוכנית עסקית — דוח אפס פנימי
A2: פרויקט פרומנצקו · כל הסכומים בשקלים
A3: מקרא: כחול = נתון להזנה ידנית · שחור = מחושב בנוסחה · ירוק = מקושר מגיליון אחר · רקע צהוב = מנוף מרכזי
A5: פרמטרים כלליים
A6: שיעור מע״מ | C6: 0.18 | E6: 18% מ-1.1.2025. בקבצי המקור חושב 17%.
A7: משך תכנון והיערכות (חודשים) | C7: 6
A8: משך ביצוע ובנייה (חודשים) | C8: 24
A9: משך אכלוס וסגירה (חודשים) | C9: 3
A10: סה״כ משך הפרויקט (חודשים) | C10: =SUM(C7:C9) -> 33
A11: מספר יחידות דיור | C11: =COUNT(דירות!A5:A34) -> 18
A13: מחירון מכירה — ₪ למ״ר, כולל מע״מ
A14: דירה רגילה | C14: 25000 | E14: גם למחסן צמוד ולמחסן נוסף של אותה דירה
A15: דירת גן | C15: 27000
A16: פנטהאוז | C16: 35000
A17: מרפסת — שיעור ממחיר הדירה | C17: 0.33 | E17: מחיר המ״ר של סוג הדירה × שיעור זה
A18: חצר — שיעור ממחיר דירת גן | C18: 0.25
A19: מקדם מחירון גלובלי | C19: 1 | E19: 1.00 = מחירון בסיס. לניתוח תרחישים.
A21: שטחים שאינם נגזרים מטבלת הדירות (מ״ר)
A22: שטחי שירות (מבואות, מדרגות, טכני) | C22: 290.05 | E22: מתוך תיק התכנון
A23: שטחי חניה ומרתפים | C23: 283.64
A24: שטחים נוספים | C24: 0
A25: מקדם ברוטו/נטו לבנייה | C25: 1 | E25: מוחל על פלדלת, שירות ושטחים נוספים
A27: עלויות בנייה ישירות — ₪ למ״ר, ללא מע״מ
A28: שטח פלדלת, שירות ושטחים נוספים | C28: 8000
A29: מרפסות זיז | C29: 3500
A30: מרפסות גג, גינות וחצרות | C30: 1500
A31: שטחי אחסנה ומחסנים | C31: 5500
A32: שטחי חניה ומרתפים | C32: 5500
A34: עלויות עקיפות ופיתוח
A35: פיתוח ואגרות בנייה (₪ למ״ר) | C35: 550
A36: תכנון, ניהול ופיקוח | C36: 0.03 | E36: מעלויות הבנייה הישירות
A37: שיווק ופרסום | C37: 0.015 | E37: משווי הפרויקט ללא מע״מ
A38: הוצאות משפטיות | C38: 0.015 | E38: משווי הפרויקט ללא מע״מ
A39: תקורה וניהול בנייה | C39: 0.04 | E39: מעלויות הבנייה הישירות
A40: עלויות מימון (לשנה) | C40: 0.03 | E40: מעלויות הבנייה הישירות
A41: שנות מימון | C41: 2
A42: חיבורי חשמל, מים וגז (₪ ליח״ד) | C42: 3500
A43: ליווי פיננסי ועמלות | C43: 0.008 | E43: מעלויות הבנייה הישירות
A44: ערבויות חוק מכר | C44: 0.008 | E44: משווי הפרויקט כולל מע״מ
A45: בלתי צפוי מראש | C45: 0.05 | E45: מעלויות הבנייה הישירות
...

Sheet דירות
A1: טבלת הדירות ואומדן ההכנסות
A2: שטח × תעריף = רכיב מחיר. ניתן להקליד סכום ידני ישירות בעמודות L / M / O / Q ולדרוס את הנוסחה.
A4: דירה מספר | B4: קומה | C4: צד/כיוון | D4: סוג הדירה | E4: גודל דירה | F4: מחסן צמוד | G4: מחסן נוסף | H4: מרפסות | I4: חצר | J4: דירה כולל צמוד | K4: תעריף מ״ר | L4: דירה סך הכל | M4: מחסן סך הכל | N4: תעריף מרפסת | O4: מרפסת סך הכל | P4: תעריף חצר | Q4: חצר סך הכל | R4: מחיר כולל מע״מ | S4: מחיר ללא מע״מ
A5: =IF($E5="","",COUNT($E$5:$E5)) -> 1 | B5: -2 | C5: צפון | D5: דירת גן | E5: 91.71 | F5: 11.37 | G5: 18.56 | I5: 129.5 | J5: =IF($E5="","",E5+F5) -> 103.08 | K5: =IF($E5="","",IF($D5=הנחות!$A$15,הנחות!$C$15,IF($D5=הנחות!$A$16,הנחות!$C$16,הנחות!$C$14))*הנחות!$C$19) -> 27000 | L5: =IF($E5="","",J5*K5) -> 2783160 | M5: =IF($E5="","",G5*K5) -> 501120 | N5: =IF($E5="","",IF($D5=הנחות!$A$16,הנחות!$C$16,הנחות!$C$14)*הנחות!$C$19*הנחות!$C$17) -> 8250 | O5: =IF($E5="","",H5*N5) -> 0 | P5: =IF($E5="","",הנחות!$C$15*הנחות!$C$19*הנחות!$C$18) -> 6750 | Q5: =IF($E5="","",I5*P5) -> 874125 | R5: =IF($E5="","",L5+M5+O5+Q5) -> 4158405 | S5: =IF($E5="","",R5/(1+הנחות!$C$6)) -> 3524072
A6: =IF($E6="","",COUNT($E$5:$E6)) -> 2 | B6: -2 | C6: דרום | D6: דירת גן | E6: 95.27 | F6: 13.7 | G6: 26.63 | I6: 101.8 | J6: =IF($E6="","",E6+F6) -> 108.97 | K6: =IF($E6="","",IF($D6=הנחות!$A$15,הנחות!$C$15,IF($D6=הנחות!$A$16,הנחות!$C$16,הנחות!$C$14))*הנחות!$C$19) -> 27000 | L6: =IF($E6="","",J6*K6) -> 2942190 | M6: =IF($E6="","",G6*K6) -> 719010 | N6: =IF($E6="","",IF($D6=הנחות!$A$16,הנחות!$C$16,הנחות!$C$14)*הנחות!$C$19*הנחות!$C$17) -> 8250 | O6: =IF($E6="","",H6*N6) -> 0 | P6: =IF($E6="","",הנחות!$C$15*הנחות!$C$19*הנחות!$C$18) -> 6750 | Q6: =IF($E6="","",I6*P6) -> 687150 | R6: =IF($E6="","",L6+M6+O6+Q6) -> 4348350 | S6: =IF($E6="","",R6/(1+הנחות!$C$6)) -> 3685042.4
A7: =IF($E7="","",COUNT($E$5:$E7)) -> 3 | B7: -1 | C7: צפון | D7: דירה רגילה | E7: 91.71 | F7: 11.37 | H7: 22.5 | J7: =IF($E7="","",E7+F7) -> 103.08 | K7: =IF($E7="","",IF($D7=הנחות!$A$15,הנחות!$C$15,IF($D7=הנחות!$A$16,הנחות!$C$16,הנחות!$C$14))*הנחות!$C$19) -> 25000 | L7: =IF($E7="","",J7*K7) -> 2577000 | M7: =IF($E7="","",G7*K7) -> 0 | N7: =IF($E7="","",IF($D7=הנחות!$A$16,הנחות!$C$16,הנחות!$C$14)*הנחות!$C$19*הנחות!$C$17) -> 8250 | O7: =IF($E7="","",H7*N7) -> 185625 | P7: =IF($E7="","",הנחות!$C$15*הנחות!$C$19*הנחות!$C$18) -> 6750 | Q7: =IF($E7="","",I7*P7) -> 0 | R7: =IF($E7="","",L7+M7+O7+Q7) -> 2762625 | S7: =IF($E7="","",R7/(1+הנחות!$C$6)) -> 2341207.6
A8: =IF($E8="","",COUNT($E$5:$E8)) -> 4 | B8: -1 | C8: דרום | D8: דירה רגילה | E8: 95.27 | F8: 13.7 | H8: 21 | J8: =IF($E8="","",E8+F8) -> 108.97 | K8: =IF($E8="","",IF($D8=הנחות!$A$15,הנחות!$C$15,IF($D8=הנחות!$A$16,הנחות!$C$16,הנחות!$C$14))*הנחות!$C$19) -> 25000 | L8: =IF($E8="","",J8*K8) -> 2724250 | M8: =IF($E8="","",G8*K8) -> 0 | N8: =IF($E8="","",IF($D8=הנחות!$A$16,הנחות!$C$16,הנחות!$C$14)*הנחות!$C$19*הנחות!$C$17) -> 8250 | O8: =IF($E8="","",H8*N8) -> 173250 | P8: =IF($E8="","",הנחות!$C$15*הנחות!$C$19*הנחות!$C$18) -> 6750 | Q8: =IF($E8="","",I8*P8) -> 0 | R8: =IF($E8="","",L8+M8+O8+Q8) -> 2897500 | S8: =IF($E8="","",R8/(1+הנחות!$C$6)) -> 2455508.5
A9: =IF($E9="","",COUNT($E$5:$E9)) -> 5 | B9: כניסה | C9: צפון | D9: דירה רגילה | E9: 91.71 | F9: 11.37 | H9: 7.1 | J9: =IF($E9="","",E9+F9) -> 103.08 | K9: =IF($E9="","",IF($D9=הנחות!$A$15,הנחות!$C$15,IF($D9=הנחות!$A$16,הנחות!$C$16,הנחות!$C$14))*הנחות!$C$19) -> 25000 | L9: =IF($E9="","",J9*K9) -> 2577000 | M9: =IF($E9="","",G9*K9) -> 0 | N9: =IF($E9="","",IF($D9=הנחות!$A$16,הנחות!$C$16,הנחות!$C$14)*הנחות!$C$19*הנחות!$C$17) -> 8250 | O9: =IF($E9="","",H9*N9) -> 58575 | P9: =IF($E9="","",הנחות!$C$15*הנחות!$C$19*הנחות!$C$18) -> 6750 | Q9: =IF($E9="","",I9*P9) -> 0 | R9: =IF($E9="","",L9+M9+O9+Q9) -> 2635575 | S9: =IF($E9="","",R9/(1+הנחות!$C$6)) -> 2233538.1
A10: =IF($E10="","",COUNT($E$5:$E10)) -> 6 | B10: כניסה | C10: דרום | D10: דירה רגילה | E10: 95.27 | F10: 13.7 | H10: 11.5 | J10: =IF($E10="","",E10+F10) -> 108.97 | K10: =IF($E10="","",IF($D10=הנחות!$A$15,הנחות!$C$15,IF($D10=הנחות!$A$16,הנחות!$C$16,הנחות!$C$14))*הנחות!$C$19) -> 25000 | L10: =IF($E10="","",J10*K10) -> 2724250 | M10: =IF($E10="","",G10*K10) -> 0 | N10: =IF($E10="","",IF($D10=הנחות!$A$16,הנחות!$C$16,הנחות!$C$14)*הנחות!$C$19*הנחות!$C$17) -> 8250 | O10: =IF($E10="","",H10*N10) -> 94875 | P10: =IF($E10="","",הנחות!$C$15*הנחות!$C$19*הנחות!$C$18) -> 6750 | Q10: =IF($E10="","",I10*P10) -> 0 | R10: =IF($E10="","",L10+M10+O10+Q10) -> 2819125 | S10: =IF($E10="","",R10/(1+הנחות!$C$6)) -> 2389089
A11: =IF($E11="","",COUNT($E$5:$E11)) -> 7 | B11: 1 | C11: צפון | D11: דירה רגילה | E11: 91.71 | H11: 13.7 | J11: =IF($E11="","",E11+F11) -> 91.71 | K11: =IF($E11="","",IF($D11=הנחות!$A$15,הנחות!$C$15,IF($D11=הנחות!$A$16,הנחות!$C$16,הנחות!$C$14))*הנחות!$C$19) -> 25000 | L11: =IF($E11="","",J11*K11) -> 2292750 | M11: =IF($E11="","",G11*K11) -> 0 | N11: =IF($E11="","",IF($D11=הנחות!$A$16,הנחות!$C$16,הנחות!$C$14)*הנחות!$C$19*הנחות!$C$17) -> 8250 | O11: =IF($E11="","",H11*N11) -> 113025 | P11: =IF($E11="","",הנחות!$C$15*הנחות!$C$19*הנחות!$C$18) -> 6750 | Q11: =IF($E11="","",I11*P11) -> 0 | R11: =IF($E11="","",L11+M11+O11+Q11) -> 2405775 | S11: =IF($E11="","",R11/(1+הנחות!$C$6)) -> 2038792.4
A12: =IF($E12="","",COUNT($E$5:$E12)) -> 8 | B12: 1 | C12: דרום | D12: דירה רגילה | E12: 95.27 | H12: 11.6 | J12: =IF($E12="","",E12+F12) -> 95.27 | K12: =IF($E12="","",IF($D12=הנחות!$A$15,הנחות!$C$15,IF($D12=הנחות!$A$16,הנחות!$C$16,הנחות!$C$14))*הנחות!$C$19) -> 25000 | L12: =IF($E12="","",J12*K12) -> 2381750 | M12: =IF($E12="","",G12*K12) -> 0 | N12: =IF($E12="","",IF($D12=הנחות!$A$16,הנחות!$C$16,הנחות!$C$14)*הנחות!$C$19*הנחות!$C$17) -> 8250 | O12: =IF($E12="","",H12*N12) -> 95700 | P12: =IF($E12="","",הנחות!$C$15*הנחות!$C$19*הנחות!$C$18) -> 6750 | Q12: =IF($E12="","",I12*P12) -> 0 | R12: =IF($E12="","",L12+M12+O12+Q12) -> 2477450 | S12: =IF($E12="","",R12/(1+הנחות!$C$6)) -> 2099533.9
A13: =IF($E13="","",COUNT($E$5:$E13)) -> 9 | B13: 2 | C13: צפון | D13: דירה רגילה | E13: 91.71 | H13: 18.8 | J13: =IF($E13="","",E13+F13) -> 91.71 | K13: =IF($E13="","",IF($D13=הנחות!$A$15,הנחות!$C$15,IF($D13=הנחות!$A$16,הנחות!$C$16,הנחות!$C$14))*הנחות!$C$19) -> 25000 | L13: =IF($E13="","",J13*K13) -> 2292750 | M13: =IF($E13="","",G13*K13) -> 0 | N13: =IF($E13="","",IF($D13=הנחות!$A$16,הנחות!$C$16,הנחות!$C$14)*הנחות!$C$19*הנחות!$C$17) -> 8250 | O13: =IF($E13="","",H13*N13) -> 155100 | P13: =IF($E13="","",הנחות!$C$15*הנחות!$C$19*הנחות!$C$18) -> 6750 | Q13: =IF($E13="","",I13*P13) -> 0 | R13: =IF($E13="","",L13+M13+O13+Q13) -> 2447850 | S13: =IF($E13="","",R13/(1+הנחות!$C$6)) -> 2074449.2
A14: =IF($E14="","",COUNT($E$5:$E14)) -> 10 | B14: 2 | C14: דרום | D14: דירה רגילה | E14: 95.27 | H14: 21.3 | J14: =IF($E14="","",E14+F14) -> 95.27 | K14: =IF($E14="","",IF($D14=הנחות!$A$15,הנחות!$C$15,IF($D14=הנחות!$A$16,הנחות!$C$16,הנחות!$C$14))*הנחות!$C$19) -> 25000 | L14: =IF($E14="","",J14*K14) -> 2381750 | M14: =IF($E14="","",G14*K14) -> 0 | N14: =IF($E14="","",IF($D14=הנחות!$A$16,הנחות!$C$16,הנחות!$C$14)*הנחות!$C$19*הנחות!$C$17) -> 8250 | O14: =IF($E14="","",H14*N14) -> 175725 | P14: =IF($E14="","",הנחות!$C$15*הנחות!$C$19*הנחות!$C$18) -> 6750 | Q14: =IF($E14="","",I14*P14) -> 0 | R14: =IF($E14="","",L14+M14+O14+Q14) -> 2557475 | S14: =IF($E14="","",R14/(1+הנחות!$C$6)) -> 2167351.7
A15: =IF($E15="","",COUNT($E$5:$E15)) -> 11 | B15: 2 | C15: מערב | D15: דירה רגילה | E15: 84.11 | H15: 16 | J15: =IF($E15="","",E15+F15) -> 84.11 | K15: =IF($E15="","",IF($D15=הנחות!$A$15,הנחות!$C$15,IF($D15=הנחות!$A$16,הנחות!$C$16,הנחות!$C$14))*הנחות!$C$19) -> 25000 | L15: =IF($E15="","",J15*K15) -> 2102750 | M15: =IF($E15="","",G15*K15) -> 0 | N15: =IF($E15="","",IF($D15=הנחות!$A$16,הנחות!$C$16,הנחות!$C$14)*הנחות!$C$19*הנחות!$C$17) -> 8250 | O15: =IF($E15="","",H15*N15) -> 132000 | P15: =IF($E15="","",הנחות!$C$15*הנחות!$C$19*הנחות!$C$18) -> 6750 | Q15: =IF($E15="","",I15*P15) -> 0 | R15: =IF($E15="","",L15+M15+O15+Q15) -> 2234750 | S15: =IF($E15="","",R15/(1+הנחות!$C$6)) -> 1893855.9
A16: =IF($E16="","",COUNT($E$5:$E16)) -> 12 | B16: 3 | C16: דרום | D16: דירה רגילה | E16: 91.71 | H16: 12.8 | J16: =IF($E16="","",E16+F16) -> 91.71 | K16: =IF($E16="","",IF($D16=הנחות!$A$15,הנחות!$C$15,IF($D16=הנחות!$A$16,הנחות!$C$16,הנחות!$C$14))*הנחות!$C$19) -> 25000 | L16: =IF($E16="","",J16*K16) -> 2292750 | M16: =IF($E16="","",G16*K16) -> 0 | N16: =IF($E16="","",IF($D16=הנחות!$A$16,הנחות!$C$16,הנחות!$C$14)*הנחות!$C$19*הנחות!$C$17) -> 8250 | O16: =IF($E16="","",H16*N16) -> 105600 | P16: =IF($E16="","",הנחות!$C$15*הנחות!$C$19*הנחות!$C$18) -> 6750 | Q16: =IF($E16="","",I16*P16) -> 0 | R16: =IF($E16="","",L16+M16+O16+Q16) -> 2398350 | S16: =IF($E16="","",R16/(1+הנחות!$C$6)) -> 2032500
A17: =IF($E17="","",COUNT($E$5:$E17)) -> 13 | B17: 3 | C17: צפון | D17: דירה רגילה | E17: 95.27 | H17: 14 | J17: =IF($E17="","",E17+F17) -> 95.27 | K17: =IF($E17="","",IF($D17=הנחות!$A$15,הנחות!$C$15,IF($D17=הנחות!$A$16,הנחות!$C$16,הנחות!$C$14))*הנחות!$C$19) -> 25000 | L17: =IF($E17="","",J17*K17) -> 2381750 | M17: =IF($E17="","",G17*K17) -> 0 | N17: =IF($E17="","",IF($D17=הנחות!$A$16,הנחות!$C$16,הנחות!$C$14)*הנחות!$C$19*הנחות!$C$17) -> 8250 | O17: =IF($E17="","",H17*N17) -> 115500 | P17: =IF($E17="","",הנחות!$C$15*הנחות!$C$19*הנחות!$C$18) -> 6750 | Q17: =IF($E17="","",I17*P17) -> 0 | R17: =IF($E17="","",L17+M17+O17+Q17) -> 2497250 | S17: =IF($E17="","",R17/(1+הנחות!$C$6)) -> 2116313.6
A18: =IF($E18="","",COUNT($E$5:$E18)) -> 14 | B18: 3 | C18: מערב | D18: דירה רגילה | E18: 84.11 | H18: 22.1 | J18: =IF($E18="","",E18+F18) -> 84.11 | K18: =IF($E18="","",IF($D18=הנחות!$A$15,הנחות!$C$15,IF($D18=הנחות!$A$16,הנחות!$C$16,הנחות!$C$14))*הנחות!$C$19) -> 25000 | L18: =IF($E18="","",J18*K18) -> 2102750 | M18: =IF($E18="","",G18*K18) -> 0 | N18: =IF($E18="","",IF($D18=הנחות!$A$16,הנחות!$C$16,הנחות!$C$14)*הנחות!$C$19*הנחות!$C$17) -> 8250 | O18: =IF($E18="","",H18*N18) -> 182325 | P18: =IF($E18="","",הנחות!$C$15*הנחות!$C$19*הנחות!$C$18) -> 6750 | Q18: =IF($E18="","",I18*P18) -> 0 | R18: =IF($E18="","",L18+M18+O18+Q18) -> 2285075 | S18: =IF($E18="","",R18/(1+הנחות!$C$6)) -> 1936504.2
A19: =IF($E19="","",COUNT($E$5:$E19)) -> 15 | B19: 4 | C19: דרום | D19: דירה רגילה | E19: 91.71 | H19: 7.4 | J19: =IF($E19="","",E19+F19) -> 91.71 | K19: =IF($E19="","",IF($D19=הנחות!$A$15,הנחות!$C$15,IF($D19=הנחות!$A$16,הנחות!$C$16,הנחות!$C$14))*הנחות!$C$19) -> 25000 | L19: =IF($E19="","",J19*K19) -> 2292750 | M19: =IF($E19="","",G19*K19) -> 0 | N19: =IF($E19="","",IF($D19=הנחות!$A$16,הנחות!$C$16,הנחות!$C$14)*הנחות!$C$19*הנחות!$C$17) -> 8250 | O19: =IF($E19="","",H19*N19) -> 61050 | P19: =IF($E19="","",הנחות!$C$15*הנחות!$C$19*הנחות!$C$18) -> 6750 | Q19: =IF($E19="","",I19*P19) -> 0 | R19: =IF($E19="","",L19+M19+O19+Q19) -> 2353800 | S19: =IF($E19="","",R19/(1+הנחות!$C$6)) -> 1994745.8
A20: =IF($E20="","",COUNT($E$5:$E20)) -> 16 | B20: 4 | C20: צפון | D20: דירה רגילה | E20: 95.27 | H20: 7.6 | J20: =IF($E20="","",E20+F20) -> 95.27 | K20: =IF($E20="","",IF($D20=הנחות!$A$15,הנחות!$C$15,IF($D20=הנחות!$A$16,הנחות!$C$16,הנחות!$C$14))*הנחות!$C$19) -> 25000 | L20: =IF($E20="","",J20*K20) -> 2381750 | M20: =IF($E20="","",G20*K20) -> 0 | N20: =IF($E20="","",IF($D20=הנחות!$A$16,הנחות!$C$16,הנחות!$C$14)*הנחות!$C$19*הנחות!$C$17) -> 8250 | O20: =IF($E20="","",H20*N20) -> 62700 | P20: =IF($E20="","",הנחות!$C$15*הנחות!$C$19*הנחות!$C$18) -> 6750 | Q20: =IF($E20="","",I20*P20) -> 0 | R20: =IF($E20="","",L20+M20+O20+Q20) -> 2444450 | S20: =IF($E20="","",R20/(1+הנחות!$C$6)) -> 2071567.8
A21: =IF($E21="","",COUNT($E$5:$E21)) -> 17 | B21: 4 | C21: מערב | D21: דירה רגילה | E21: 84.11 | H21: 6.5 | J21: =IF($E21="","",E21+F21) -> 84.11 | K21: =IF($E21="","",IF($D21=הנחות!$A$15,הנחות!$C$15,IF($D21=הנחות!$A$16,הנחות!$C$16,הנחות!$C$14))*הנחות!$C$19) -> 25000 | L21: =IF($E21="","",J21*K21) -> 2102750 | M21: =IF($E21="","",G21*K21) -> 0 | N21: =IF($E21="","",IF($D21=הנחות!$A$16,הנחות!$C$16,הנחות!$C$14)*הנחות!$C$19*הנחות!$C$17) -> 8250 | O21: =IF($E21="","",H21*N21) -> 53625 | P21: =IF($E21="","",הנחות!$C$15*הנחות!$C$19*הנחות!$C$18) -> 6750 | Q21: =IF($E21="","",I21*P21) -> 0 | R21: =IF($E21="","",L21+M21+O21+Q21) -> 2156375 | S21: =IF($E21="","",R21/(1+הנחות!$C$6)) -> 1827436.4
A22: =IF($E22="","",COUNT($E$5:$E22)) -> 18 | B22: 5 | C22: פנטהאוז | D22: פנטהאוז | E22: 96.95 | F22: 11.37 | G22: 60.43 | H22: 87.7 | J22: =IF($E22="","",E22+F22) -> 108.32 | K22: =IF($E22="","",IF($D22=הנחות!$A$15,הנחות!$C$15,IF($D22=הנחות!$A$16,הנחות!$C$16,הנחות!$C$14))*הנחות!$C$19) -> 35000 | L22: =IF($E22="","",J22*K22) -> 3791200 | M22: =IF($E22="","",G22*K22) -> 2115050 | N22: =IF($E22="","",IF($D22=הנחות!$A$16,הנחות!$C$16,הנחות!$C$14)*הנחות!$C$19*הנחות!$C$17) -> 11550 | O22: =IF($E22="","",H22*N22) -> 1012935 | P22: =IF($E22="","",הנחות!$C$15*הנחות!$C$19*הנחות!$C$18) -> 6750 | Q22: =IF($E22="","",I22*P22) -> 0 | R22: =IF($E22="","",L22+M22+O22+Q22) -> 6919185 | S22: =IF($E22="","",R22/(1+הנחות!$C$6)) -> 5863716.1
A23: =IF($E23="","",COUNT($E$5:$E23)) | D23: דירה רגילה | J23: =IF($E23="","",E23+F23) | K23: =IF($E23="","",IF($D23=הנחות!$A$15,הנחות!$C$15,IF($D23=הנחות!$A$16,הנחות!$C$16,הנחות!$C$14))*הנחות!$C$19) | L23: =IF($E23="","",J23*K23) | M23: =IF($E23="","",G23*K23) | N23: =IF($E23="","",IF($D23=הנחות!$A$16,הנחות!$C$16,הנחות!$C$14)*הנחות!$C$19*הנחות!$C$17) | O23: =IF($E23="","",H23*N23) | P23: =IF($E23="","",הנחות!$C$15*הנחות!$C$19*הנחות!$C$18) | Q23: =IF($E23="","",I23*P23) | R23: =IF($E23="","",L23+M23+O23+Q23) | S23: =IF($E23="","",R23/(1+הנחות!$C$6))
A24: =IF($E24="","",COUNT($E$5:$E24)) | D24: דירה רגילה | J24: =IF($E24="","",E24+F24) | K24: =IF($E24="","",IF($D24=הנחות!$A$15,הנחות!$C$15,IF($D24=הנחות!$A$16,הנחות!$C$16,הנחות!$C$14))*הנחות!$C$19) | L24: =IF($E24="","",J24*K24) | M24: =IF($E24="","",G24*K24) | N24: =IF($E24="","",IF($D24=הנחות!$A$16,הנחות!$C$16,הנחות!$C$14)*הנחות!$C$19*הנחות!$C$17) | O24: =IF($E24="","",H24*N24) | P24: =IF($E24="","",הנחות!$C$15*הנחות!$C$19*הנחות!$C$18) | Q24: =IF($E24="","",I24*P24) | R24: =IF($E24="","",L24+M24+O24+Q24) | S24: =IF($E24="","",R24/(1+הנחות!$C$6))
A25: =IF($E25="","",COUNT($E$5:$E25)) | D25: דירה רגילה | J25: =IF($E25="","",E25+F25) | K25: =IF($E25="","",IF($D25=הנחות!$A$15,הנחות!$C$15,IF($D25=הנחות!$A$16,הנחות!$C$16,הנחות!$C$14))*הנחות!$C$19) | L25: =IF($E25="","",J25*K25) | M25: =IF($E25="","",G25*K25) | N25: =IF($E25="","",IF($D25=הנחות!$A$16,הנחות!$C$16,הנחות!$C$14)*הנחות!$C$19*הנחות!$C$17) | O25: =IF($E25="","",H25*N25) | P25: =IF($E25="","",הנחות!$C$15*הנחות!$C$19*הנחות!$C$18) | Q25: =IF($E25="","",I25*P25) | R25: =IF($E25="","",L25+M25+O25+Q25) | S25: =IF($E25="","",R25/(1+הנחות!$C$6))
A26: =IF($E26="","",COUNT($E$5:$E26)) | D26: דירה רגילה | J26: =IF($E26="","",E26+F26) | K26: =IF($E26="","",IF($D26=הנחות!$A$15,הנחות!$C$15,IF($D26=הנחות!$A$16,הנחות!$C$16,הנחות!$C$14))*הנחות!$C$19) | L26: =IF($E26="","",J26*K26) | M26: =IF($E26="","",G26*K26) | N26: =IF($E26="","",IF($D26=הנחות!$A$16,הנחות!$C$16,הנחות!$C$14)*הנחות!$C$19*הנחות!$C$17) | O26: =IF($E26="","",H26*N26) | P26: =IF($E26="","",הנחות!$C$15*הנחות!$C$19*הנחות!$C$18) | Q26: =IF($E26="","",I26*P26) | R26: =IF($E26="","",L26+M26+O26+Q26) | S26: =IF($E26="","",R26/(1+הנחות!$C$6))
A27: =IF($E27="","",COUNT($E$5:$E27)) | D27: דירה רגילה | J27: =IF($E27="","",E27+F27) | K27: =IF($E27="","",IF($D27=הנחות!$A$15,הנחות!$C$15,IF($D27=הנחות!$A$16,הנחות!$C$16,הנחות!$C$14))*הנחות!$C$19) | L27: =IF($E27="","",J27*K27) | M27: =IF($E27="","",G27*K27) | N27: =IF($E27="","",IF($D27=הנחות!$A$16,הנחות!$C$16,הנחות!$C$14)*הנחות!$C$19*הנחות!$C$17) | O27: =IF($E27="","",H27*N27) | P27: =IF($E27="","",הנחות!$C$15*הנחות!$C$19*הנחות!$C$18) | Q27: =IF($E27="","",I27*P27) | R27: =IF($E27="","",L27+M27+O27+Q27) | S27: =IF($E27="","",R27/(1+הנחות!$C$6))
A28: =IF($E28="","",COUNT($E$5:$E28)) | D28: דירה רגילה | J28: =IF($E28="","",E28+F28) | K28: =IF($E28="","",IF($D28=הנחות!$A$15,הנחות!$C$15,IF($D28=הנחות!$A$16,הנחות!$C$16,הנחות!$C$14))*הנחות!$C$19) | L28: =IF($E28="","",J28*K28) | M28: =IF($E28="","",G28*K28) | N28: =IF($E28="","",IF($D28=הנחות!$A$16,הנחות!$C$16,הנחות!$C$14)*הנחות!$C$19*הנחות!$C$17) | O28: =IF($E28="","",H28*N28) | P28: =IF($E28="","",הנחות!$C$15*הנחות!$C$19*הנחות!$C$18) | Q28: =IF($E28="","",I28*P28) | R28: =IF($E28="","",L28+M28+O28+Q28) | S28: =IF($E28="","",R28/(1+הנחות!$C$6))
A29: =IF($E29="","",COUNT($E$5:$E29)) | D29: דירה רגילה | J29: =IF($E29="","",E29+F29) | K29: =IF($E29="","",IF($D29=הנחות!$A$15,הנחות!$C$15,IF($D29=הנחות!$A$16,הנחות!$C$16,הנחות!$C$14))*הנחות!$C$19) | L29: =IF($E29="","",J29*K29) | M29: =IF($E29="","",G29*K29) | N29: =IF($E29="","",IF($D29=הנחות!$A$16,הנחות!$C$16,הנחות!$C$14)*הנחות!$C$19*הנחות!$C$17) | O29: =IF($E29="","",H29*N29) | P29: =IF($E29="","",הנחות!$C$15*הנחות!$C$19*הנחות!$C$18) | Q29: =IF($E29="","",I29*P29) | R29: =IF($E29="","",L29+M29+O29+Q29) | S29: =IF($E29="","",R29/(1+הנחות!$C$6))
A30: =IF($E30="","",COUNT($E$5:$E30)) | D30: דירה רגילה | J30: =IF($E30="","",E30+F30) | K30: =IF($E30="","",IF($D30=הנחות!$A$15,הנחות!$C$15,IF($D30=הנחות!$A$16,הנחות!$C$16,הנחות!$C$14))*הנחות!$C$19) | L30: =IF($E30="","",J30*K30) | M30: =IF($E30="","",G30*K30) | N30: =IF($E30="","",IF($D30=הנחות!$A$16,הנחות!$C$16,הנחות!$C$14)*הנחות!$C$19*הנחות!$C$17) | O30: =IF($E30="","",H30*N30) | P30: =IF($E30="","",הנחות!$C$15*הנחות!$C$19*הנחות!$C$18) | Q30: =IF($E30="","",I30*P30) | R30: =IF($E30="","",L30+M30+O30+Q30) | S30: =IF($E30="","",R30/(1+הנחות!$C$6))
A31: =IF($E31="","",COUNT($E$5:$E31)) | D31: דירה רגילה | J31: =IF($E31="","",E31+F31) | K31: =IF($E31="","",IF($D31=הנחות!$A$15,הנחות!$C$15,IF($D31=הנחות!$A$16,הנחות!$C$16,הנחות!$C$14))*הנחות!$C$19) | L31: =IF($E31="","",J31*K31) | M31: =IF($E31="","",G31*K31) | N31: =IF($E31="","",IF($D31=הנחות!$A$16,הנחות!$C$16,הנחות!$C$14)*הנחות!$C$19*הנחות!$C$17) | O31: =IF($E31="","",H31*N31) | P31: =IF($E31="","",הנחות!$C$15*הנחות!$C$19*הנחות!$C$18) | Q31: =IF($E31="","",I31*P31) | R31: =IF($E31="","",L31+M31+O31+Q31) | S31: =IF($E31="","",R31/(1+הנחות!$C$6))
A32: =IF($E32="","",COUNT($E$5:$E32)) | D32: דירה רגילה | J32: =IF($E32="","",E32+F32) | K32: =IF($E32="","",IF($D32=הנחות!$A$15,הנחות!$C$15,IF($D32=הנחות!$A$16,הנחות!$C$16,הנחות!$C$14))*הנחות!$C$19) | L32: =IF($E32="","",J32*K32) | M32: =IF($E32="","",G32*K32) | N32: =IF($E32="","",IF($D32=הנחות!$A$16,הנחות!$C$16,הנחות!$C$14)*הנחות!$C$19*הנחות!$C$17) | O32: =IF($E32="","",H32*N32) | P32: =IF($E32="","",הנחות!$C$15*הנחות!$C$19*הנחות!$C$18) | Q32: =IF($E32="","",I32*P32) | R32: =IF($E32="","",L32+M32+O32+Q32) | S32: =IF($E32="","",R32/(1+הנחות!$C$6))
A33: =IF($E33="","",COUNT($E$5:$E33)) | D33: דירה רגילה | J33: =IF($E33="","",E33+F33) | K33: =IF($E33="","",IF($D33=הנחות!$A$15,הנחות!$C$15,IF($D33=הנחות!$A$16,הנחות!$C$16,הנחות!$C$14))*הנחות!$C$19) | L33: =IF($E33="","",J33*K33) | M33: =IF($E33="","",G33*K33) | N33: =IF($E33="","",IF($D33=הנחות!$A$16,הנחות!$C$16,הנחות!$C$14)*הנחות!$C$19*הנחות!$C$17) | O33: =IF($E33="","",H33*N33) | P33: =IF($E33="","",הנחות!$C$15*הנחות!$C$19*הנחות!$C$18) | Q33: =IF($E33="","",I33*P33) | R33: =IF($E33="","",L33+M33+O33+Q33) | S33: =IF($E33="","",R33/(1+הנחות!$C$6))
A34: =IF($E34="","",COUNT($E$5:$E34)) | D34: דירה רגילה | J34: =IF($E34="","",E34+F34) | K34: =IF($E34="","",IF($D34=הנחות!$A$15,הנחות!$C$15,IF($D34=הנחות!$A$16,הנחות!$C$16,הנחות!$C$14))*הנחות!$C$19) | L34: =IF($E34="","",J34*K34) | M34: =IF($E34="","",G34*K34) | N34: =IF($E34="","",IF($D34=הנחות!$A$16,הנחות!$C$16,הנחות!$C$14)*הנחות!$C$19*הנחות!$C$17) | O34: =IF($E34="","",H34*N34) | P34: =IF($E34="","",הנחות!$C$15*הנחות!$C$19*הנחות!$C$18) | Q34: =IF($E34="","",I34*P34) | R34: =IF($E34="","",L34+M34+O34+Q34) | S34: =IF($E34="","",R34/(1+הנחות!$C$6))
A35: ↑ שורות ריקות מוכנות להוספת דירות — מלא קומה, צד, סוג ושטחים, וכל המודל יתעדכן
A36: סה״כ | D36: =COUNT(A5:A34)&" יח״ד" -> 18 יח״ד | E36: =SUM(E5:E34) -> 1658.14 | F36: =SUM(F5:F34) -> 86.58 | G36: =SUM(G5:G34) -> 105.62 | H36: =SUM(H5:H34) -> 301.6 | I36: =SUM(I5:I34) -> 231.3 | J36: =SUM(J5:J34) -> 1744.72 | L36: =SUM(L5:L34) -> 45125300 | M36: =SUM(M5:M34) -> 3335180 | O36: =SUM(O5:O34) -> 2777610 | Q36: =SUM(Q5:Q34) -> 1561275 | R36: =SUM(R5:R34) -> 52799365 | S36: =SUM(S5:S34) -> 44745225
A38: התעריפים בעמודות K, N, P נגזרים מסוג הדירה ומהמחירון בגיליון ״הנחות״. שינוי המחירון מתעדכן כאן ובכל שאר הגיליונות.
A39: מספור הדירות בעמודה A מתעדכן אוטומטית לפי השורות המאוכלסות.

Sheet עלויות
A1: אומדן עלויות הפרויקט
A2: כל הסכומים ללא מע״מ, למעט ערבויות חוק מכר המחושבות משווי כולל מע״מ.
A4: א. עלויות בנייה ישירות
A5: תיאור | B5: שטח (מ״ר) | C5: עלות למ״ר | D5: סה״כ עלות | E5: % מהישיר
A6: שטח פלדלת, שירות ושטחים נוספים | B6: =(דירות!E36+הנחות!$C$22+הנחות!$C$24)*הנחות!$C$25 -> 1948.19 | C6: =הנחות!$C$28 -> 8000 | D6: =B6*C6 -> 15585520 | E6: =IFERROR(D6/$D$11,0) -> 0.79496909
A7: מרפסות זיז | B7: =דירות!H36 -> 301.6 | C7: =הנחות!$C$29 -> 3500 | D7: =B7*C7 -> 1055600 | E7: =IFERROR(D7/$D$11,0) -> 0.053842885
A8: מרפסות גג, גינות וחצרות | B8: =דירות!I36 -> 231.3 | C8: =הנחות!$C$30 -> 1500 | D8: =B8*C8 -> 346950 | E8: =IFERROR(D8/$D$11,0) -> 0.017696845
A9: שטחי אחסנה ומחסנים | B9: =דירות!F36+דירות!G36 -> 192.2 | C9: =הנחות!$C$31 -> 5500 | D9: =B9*C9 -> 1057100 | E9: =IFERROR(D9/$D$11,0) -> 0.053919396
A10: שטחי חניה ומרתפים | B10: =הנחות!$C$23 -> 283.64 | C10: =הנחות!$C$32 -> 5500 | D10: =B10*C10 -> 1560020 | E10: =IFERROR(D10/$D$11,0) -> 0.079571787
A11: סה״כ עלויות בנייה ישירות | B11: =SUM(B6:B10) -> 2956.93 | D11: =SUM(D6:D10) -> 19605190 | E11: =IFERROR(D11/$D$11,0) -> 1
A13: ב. עלויות עקיפות ופיתוח
A14: תיאור | B14: בסיס החישוב | C14: שיעור / תעריף | D14: סה״כ עלות | E14: קישור לתזרים
A15: פיתוח ואגרות בנייה | B15: =B6+B7+B9+B10 -> 2725.63 | C15: =הנחות!$C$35 -> 550 | D15: =B15*C15 -> 1499096.5 | E15: בנייה
A16: תכנון, ניהול ופיקוח | B16: =$D$11 -> 19605190 | C16: =הנחות!$C$36 -> 0.03 | D16: =B16*C16 -> 588155.7 | E16: בנייה
A17: שיווק ופרסום | B17: =סיכום!$C$7 -> 44745225 | C17: =הנחות!$C$37 -> 0.015 | D17: =B17*C17 -> 671178.37 | E17: מכירות
A18: הוצאות משפטיות | B18: =סיכום!$C$7 -> 44745225 | C18: =הנחות!$C$38 -> 0.015 | D18: =B18*C18 -> 671178.37 | E18: מכירות
A19: תקורה וניהול בנייה | B19: =$D$11 -> 19605190 | C19: =הנחות!$C$39 -> 0.04 | D19: =B19*C19 -> 784207.6 | E19: בנייה
A20: עלויות מימון | B20: =$D$11 -> 19605190 | C20: =הנחות!$C$40 -> 0.03 | D20: =B20*C20*הנחות!$C$41 -> 1176311.4 | E20: בנייה
A21: חיבורי חשמל, מים וגז | B21: =הנחות!$C$11 -> 18 | C21: =הנחות!$C$42 -> 3500 | D21: =B21*C21 -> 63000 | E21: בנייה
A22: ליווי פיננסי ועמלות | B22: =$D$11 -> 19605190 | C22: =הנחות!$C$43 -> 0.008 | D22: =B22*C22 -> 156841.52 | E22: בנייה
A23: ערבויות חוק מכר | B23: =סיכום!$C$6 -> 52799365 | C23: =הנחות!$C$44 -> 0.008 | D23: =B23*C23 -> 422394.92 | E23: מכירות
A24: בלתי צפוי מראש | B24: =$D$11 -> 19605190 | C24: =הנחות!$C$45 -> 0.05 | D24: =B24*C24 -> 980259.5 | E24: בנייה
A25: שכ״ד לדיירי המבנה הקיים | D25: =הנחות!$C$46 -> 0 | E25: בנייה
A26: פינוי, הובלה ואחסון | D26: =הנחות!$C$47 -> 0 | E26: בנייה
A27: סה״כ עלויות עקיפות | D27: =SUM(D15:D26) -> 7012623.9
A28: מזה — נגזר מקצב הבנייה | D28: =SUMIF($E$15:$E$26,"בנייה",$D$15:$D$26) -> 5247872.2
A29: מזה — נגזר מקצב המכירות | D29: =SUMIF($E$15:$E$26,"מכירות",$D$15:$D$26) -> 1764751.7
A31: ג. רכישת הקרקע ומסים
A32: תיאור | B32: בסיס | C32: שיעור | D32: סה״כ
A33: עלות רכישת הקרקע / הזכויות | D33: =הנחות!$C$50 -> 8500000
A34: מס רכישה | B34: =הנחות!$C$50 -> 8500000 | C34: =הנחות!$C$51 -> 0.06 | D34: =B34*C34 -> 510000
A35: היטל השבחה ומסי ועדה | D35: =הנחות!$C$52 -> 250000
A36: עלויות נלוות (שמאות, עו״ד, תיווך) | D36: =הנחות!$C$53 -> 0
A37: סה״כ עלות רכישה | D37: =SUM(D33:D36) -> 9260000
A39: סה״כ עלות הקמת הפרויקט | D39: =D11+D27+D37 -> 35877814

Sheet סיכום
A1: סיכום עלויות, הכנסות ורווחיות
A2: הריכוז הכלכלי של הפרויקט — הבסיס להחלטת האשראי.
A4: הכנסות
A5: מספר יחידות דיור | C5: =הנחות!$C$11 -> 18
A6: סה״כ שווי מכירות כולל מע״מ | C6: =דירות!R36 -> 52799365
A7: סה״כ הכנסות ללא מע״מ | C7: =C6/(1+הנחות!$C$6) -> 44745225 | D7: =C7/$C$7 -> 1
A8: מחיר ממוצע ליח״ד (כולל מע״מ) | C8: =IFERROR(C6/C5,0) -> 2933298.1
A9: מחיר ממוצע למ״ר דירתי (כולל מע״מ) | C9: =IFERROR(C6/דירות!E36,0) -> 31842.525
A11: עלויות
A12: עלות רכישת קרקע, מסים והיטלים | C12: =עלויות!$D$37 -> 9260000 | D12: =C12/$C$7 -> 0.20694946
A13: עלויות בנייה ישירות | C13: =עלויות!$D$11 -> 19605190 | D13: =C13/$C$7 -> 0.43815156
A14: עלויות עקיפות, פיתוח ומימון | C14: =עלויות!$D$27 -> 7012623.9 | D14: =C14/$C$7 -> 0.1567234
A15: סה״כ עלות הקמת הפרויקט | C15: =SUM(C12:C14) -> 35877814 | D15: =C15/$C$7 -> 0.80182442
A17: רווח יזמי צפוי לפני מס | C17: =C7-C15 -> 8867410.7 | D17: =IFERROR(C17/C7,0) -> 0.19817558
A20: מדדי רווחיות
A21: רווח יזמי מהעלות | C21: =IFERROR(C17/C15,0) -> 0.24715583 | F21: סף מקובל בבנקים 20%–25%
A22: שיעור רווח מהמחזור | C22: =IFERROR(C17/C7,0) -> 0.19817558 | F22: סף מקובל 15%–18%
A23: עלות כוללת ליח״ד | C23: =IFERROR(C15/C5,0) -> 1993211.9
A24: רווח ליח״ד | C24: =IFERROR(C17/C5,0) -> 492633.93
A25: עלות בנייה ממוצעת למ״ר בנוי | C25: =IFERROR(עלויות!D11/עלויות!B11,0) -> 6630.2516
A27: מבנה מימון וליווי בנקאי
A28: הון עצמי נדרש | C28: =C15*הנחות!$C$56 -> 8969453.5
A29: יחס הון עצמי לעלות | C29: =IFERROR(C28/C15,0) -> 0.25 | F29: סף מקובל ≥ 20%
A30: מסגרת ליווי בנקאית | C30: =MAX(0,C15-C28) -> 26908360 | F30: עלות הפרויקט בניכוי ההון העצמי
A31: שיא ניצול אשראי בפועל | C31: =תזרים!$N$16 -> 0 | F31: מתוך גיליון התזרים
A32: תשואה על ההון (כל התקופה) | C32: =IFERROR(C17/C28,0) -> 0.9886233
A33: תשואה על ההון (שנתי ממוצע) | C33: =IFERROR((1+C32)^(12/הנחות!$C$10)-1,0) -> 0.28399861
A34: מכירות מוקדמות נדרשות | C34: =C6*הנחות!$C$58 -> 18479778
A35: עודף הכנסות צפוי (Surplus) | C35: =C7-C15 -> 8867410.7 | F35: חייב להיות חיובי
A36: יחס כיסוי הכנסות למסגרת | C36: =IFERROR(C7/C30,0) -> 1.6628744 | F36: סף מקובל ≥ 1.3×
A38: נקודת איזון | F38: עלויות השיווק, המשפטיות והערבויות נגזרות מהמחזור ולכן משתנות יחד עם המחיר
A39: עלויות הנגזרות מהמחזור | C39: =C7*(הנחות!$C$37+הנחות!$C$38)+C6*הנחות!$C$44 -> 1764751.7
A40: עלויות שאינן תלויות במחיר | C40: =C15-C39 -> 34113062
A41: מקדם מחיר לאיזון | C41: =IFERROR(C40/(C7-C39),0) -> 0.79368746
A42: ירידת מחירים מותרת עד האיזון | C42: =1-C41 -> 0.20631254
A43: מחיר מ״ר לאיזון (דירה רגילה) | C43: =הנחות!$C$14*הנחות!$C$19*C41 -> 19842.186
A44: שיעור מכירות לכיסוי האשראי | C44: =IFERROR((C15-C28)/C7,0) -> 0.60136832

Sheet תזרים
A1: תזרים מזומנים רבעוני
A2: פריסה על פני 11 רבעונים. אחוזי ההתקדמות בשורות 5–6 ניתנים לעריכה — הסכומים מנורמלים אוטומטית.
A4: סעיף | B4: רבעון 1 | C4: רבעון 2 | D4: רבעון 3 | E4: רבעון 4 | F4: רבעון 5 | G4: רבעון 6 | H4: רבעון 7 | I4: רבעון 8 | J4: רבעון 9 | K4: רבעון 10 | L4: רבעון 11 | M4: סה״כ
A5: % התקדמות בנייה | B5: 0.003 | C5: 0.003 | D5: 0.039 | E5: 0.089 | F5: 0.13 | G5: 0.156 | H5: 0.166 | I5: 0.156 | J5: 0.13 | K5: 0.089 | L5: 0.039 | M5: =SUM(B5:L5) -> 1
A6: % גביית מכירות | B6: 0 | C6: 0 | D6: 0.009 | E6: 0.026 | F6: 0.047 | G6: 0.072 | H6: 0.101 | I6: 0.132 | J6: 0.167 | K6: 0.204 | L6: 0.243 | M6: =SUM(B6:L6) -> 1.001
A8: רכישת קרקע ומסים | B8: =IF(1=1,-עלויות!$D$37,0) -> -9260000 | C8: =IF(2=1,-עלויות!$D$37,0) -> 0 | D8: =IF(3=1,-עלויות!$D$37,0) -> 0 | E8: =IF(4=1,-עלויות!$D$37,0) -> 0 | F8: =IF(5=1,-עלויות!$D$37,0) -> 0 | G8: =IF(6=1,-עלויות!$D$37,0) -> 0 | H8: =IF(7=1,-עלויות!$D$37,0) -> 0 | I8: =IF(8=1,-עלויות!$D$37,0) -> 0 | J8: =IF(9=1,-עלויות!$D$37,0) -> 0 | K8: =IF(10=1,-עלויות!$D$37,0) -> 0 | L8: =IF(11=1,-עלויות!$D$37,0) -> 0 | M8: =SUM(B8:L8) -> -9260000
A9: עלויות בנייה ישירות | B9: =-עלויות!$D$11*B$5/SUM($B$5:$L$5) -> -58815.57 | C9: =-עלויות!$D$11*C$5/SUM($B$5:$L$5) -> -58815.57 | D9: =-עלויות!$D$11*D$5/SUM($B$5:$L$5) -> -764602.41 | E9: =-עלויות!$D$11*E$5/SUM($B$5:$L$5) -> -1744861.9 | F9: =-עלויות!$D$11*F$5/SUM($B$5:$L$5) -> -2548674.7 | G9: =-עלויות!$D$11*G$5/SUM($B$5:$L$5) -> -3058409.6 | H9: =-עלויות!$D$11*H$5/SUM($B$5:$L$5) -> -3254461.5 | I9: =-עלויות!$D$11*I$5/SUM($B$5:$L$5) -> -3058409.6 | ... L9: =-עלויות!$D$11*L$5/SUM($B$5:$L$5) -> -764602.41 | M9: =SUM(B9:L9) -> -19605190
A10: עלויות עקיפות ופיתוח | B10: =-(עלויות!$D$28*B$5/SUM($B$5:$L$5)+עלויות!$D$29*B$6/SUM($B$6:$L$6)) -> -15743.617 | C10: =-(עלויות!$D$28*C$5/SUM($B$5:$L$5)+עלויות!$D$29*C$6/SUM($B$6:$L$6)) -> -15743.617 | D10: =-(עלויות!$D$28*D$5/SUM($B$5:$L$5)+עלויות!$D$29*D$6/SUM($B$6:$L$6)) -> -220533.91 | E10: =-(עלויות!$D$28*E$5/SUM($B$5:$L$5)+עלויות!$D$29*E$6/SUM($B$6:$L$6)) -> -512898.33 | F10: =-(עלויות!$D$28*F$5/SUM($B$5:$L$5)+עלויות!$D$29*F$6/SUM($B$6:$L$6)) -> -765083.86 | G10: =-(עלויות!$D$28*G$5/SUM($B$5:$L$5)+עלויות!$D$29*G$6/SUM($B$6:$L$6)) -> -945603.25 | H10: =-(עלויות!$D$28*H$5/SUM($B$5:$L$5)+עלויות!$D$29*H$6/SUM($B$6:$L$6)) -> -1049208.6 | I10: =-(עלויות!$D$28*I$5/SUM($B$5:$L$5)+עלויות!$D$29*I$6/SUM($B$6:$L$6)) -> -1051382.6 | ... L10: =-(עלויות!$D$28*L$5/SUM($B$5:$L$5)+עלויות!$D$29*L$6/SUM($B$6:$L$6)) -> -633073.26 | M10: =SUM(B10:L10) -> -7012623.9
A11: סה״כ תשלומים | B11: =SUM(B8:B10) -> -9334559.2 | C11: =SUM(C8:C10) -> -74559.187 | D11: =SUM(D8:D10) -> -985136.32 | E11: =SUM(E8:E10) -> -2257760.2 | F11: =SUM(F8:F10) -> -3313758.6 | G11: =SUM(G8:G10) -> -4004012.9 | H11: =SUM(H8:H10) -> -4303670.2 | I11: =SUM(I8:I10) -> -4109792.2 | ... L11: =SUM(L8:L10) -> -1397675.7 | M11: =SUM(B11:L11) -> -35877814
A12: תקבולי מכירות (ללא מע״מ) | B12: =סיכום!$C$7*B$6/SUM($B$6:$L$6) -> 0 | C12: =סיכום!$C$7*C$6/SUM($B$6:$L$6) -> 0 | D12: =סיכום!$C$7*D$6/SUM($B$6:$L$6) -> 402304.72 | E12: =סיכום!$C$7*E$6/SUM($B$6:$L$6) -> 1162213.6 | F12: =סיכום!$C$7*F$6/SUM($B$6:$L$6) -> 2100924.6 | G12: =סיכום!$C$7*G$6/SUM($B$6:$L$6) -> 3218437.7 | H12: =סיכום!$C$7*H$6/SUM($B$6:$L$6) -> 4514752.9 | I12: =סיכום!$C$7*I$6/SUM($B$6:$L$6) -> 5900469.2 | ... L12: =סיכום!$C$7*L$6/SUM($B$6:$L$6) -> 10862227 | M12: =SUM(B12:L12) -> 44745225
A13: תזרים נטו לתקופה | B13: =B11+B12 -> -9334559.2 | C13: =C11+C12 -> -74559.187 | D13: =D11+D12 -> -582831.61 | E13: =E11+E12 -> -1095546.6 | F13: =F11+F12 -> -1212833.9 | G13: =G11+G12 -> -785575.16 | H13: =H11+H12 -> 211082.75 | I13: =I11+I12 -> 1790677 | ... L13: =L11+L12 -> 9464551.7 | M13: =SUM(B13:L13) -> 8867410.7
A14: תזרים מצטבר | B14: =B13 -> -9334559.2 | C14: =B14+C13 -> -9409118.4 | D14: =C14+D13 -> -9991950 | E14: =D14+E13 -> -11087497 | F14: =E14+F13 -> -12300331 | G14: =F14+G13 -> -13085906 | H14: =G14+H13 -> -12874823 | I14: =H14+I13 -> -11084146 | J14: =I14+J13 -> -7144475.7 | ... L14: =K14+L13 -> 8867410.7 | M14: =L14 -> 8867410.7
A15: צריכת מקורות מצטברת | B15: =MAX(0,-B14) -> 9334559.2 | C15: =MAX(0,-C14) -> 9409118.4 | D15: =MAX(0,-D14) -> 9991950 | E15: =MAX(0,-E14) -> 11087497 | F15: =MAX(0,-F14) -> 12300331 | G15: =MAX(0,-G14) -> 13085906 | H15: =MAX(0,-H14) -> 12874823 | I15: =MAX(0,-I14) -> 11084146 | ... L15: =MAX(0,-L14) -> 0 | M15: =MAX(B15:L15) -> 13085906
A16: יתרת אשראי בנקאי | B16: =MAX(0,-B14-סיכום!$C$28) -> 365105.72 | C16: =MAX(0,-C14-סיכום!$C$28) -> 439664.9 | D16: =MAX(0,-D14-סיכום!$C$28) -> 1022496.5 | E16: =MAX(0,-E14-סיכום!$C$28) -> 2118043.1 | F16: =MAX(0,-F14-סיכום!$C$28) -> 3330877.1 | G16: =MAX(0,-G14-סיכום!$C$28) -> 4116452.2 | H16: =MAX(0,-H14-סיכום!$C$28) -> 3905369.5 | I16: =MAX(0,-I14-סיכום!$C$28) -> 2114692.5 | ... L16: =MAX(0,-L14-סיכום!$C$28) -> 0 | M16: =MAX(B16:L16) -> 4116452.2
A18: שיא צריכת מקורות (הון עצמי + אשראי) | B18: =M15 -> 13085906
A19: שיא ניצול אשראי בנקאי בפועל | B19: =M16 -> 4116452.2
A20: ריבית מצטברת על יתרת האשראי | B20: =(((0+B16)/2)+((B16+C16)/2)+((C16+D16)/2)+((D16+E16)/2)+((E16+F16)/2)+((F16+G16)/2)+((G16+H16)/2)+((H16+I16)/2)+((I16+J16)/2)+((J16+K16)/2)+((K16+L16)/2))*הנחות!$C$57/4 -> 282956.4
A21: עלות מימון שהוזנה בסעיף העקיפות | B21: =עלויות!$D$20 -> 1176311.4
A22: כרית ביטחון במימון | B22: =B21-B20 -> 893355

Sheet רגישות
A1: ניתוח רגישות — רווח יזמי מהעלות
A2: שינוי אחיד במחירי המכירה מול שינוי בעלויות הבנייה. התא המסומן הוא תרחיש הבסיס.
A4: שינוי בעלויות הבנייה ↓ / שינוי במחירי המכירה → | B4: -0.1 | C4: -0.075 | D4: -0.05 | E4: -0.025 | F4: 0 | G4: 0.025 | H4: 0.05 | I4: 0.075 | J4: 0.1
A5: -0.1 | B5: =IFERROR((סיכום!$C$7*(1+B$4)-(עלויות!$D$37+עלויות!$D$11*(1+$A5)+(עלויות!$D$15+עלויות!$D$11*(1+$A5)*(הנחות!$C$36+הנחות!$C$39+הנחות!$C$43+הנחות!$C$45)+עלויות!$D$11*(1+$A5)*הנחות!$C$40*הנחות!$C$41+סיכום!$C$7*(1+B$4)*(הנחות!$C$37+הנחות!$C$38)+סיכום!$C$6*(1+B$4)*הנחות!$C$44+עלויות!$D$21+עלויות!$D$25+עלויות!$D$26)))/(עלויות!$D$37+עלויות!$D$11*(1+$A5)+(עלויות!$D$15+עלויות!$D$11*(1+$A5)*(הנחות!$C$36+הנחות!$C$39+הנחות!$C$43+הנחות!$C$45)+עלויות!$D$11*(1+$A5)*הנחות!$C$40*הנחות!$C$41+סיכום!$C$7*(1+B$4)*(הנחות!$C$37+הנחות!$C$38)+סיכום!$C$6*(1+B$4)*הנחות!$C$44+עלויות!$D$21+עלויות!$D$25+עלויות!$D$26)),0) -> 0.20671251 | C5: =IFERROR((סיכום!$C$7*(1+C$4)-(עלויות!$D$37+עלויות!$D$11*(1+$A5)+(עלויות!$D$15+עלויות!$D$11*(1+$A5)*(הנחות!$C$36+הנחות!$C$39+הנחות!$C$43+הנחות!$C$45)+עלויות!$D$11*(1+$A5)*הנחות!$C$40*הנחות!$C$41+סיכום!$C$7*(1+C$4)*(הנחות!$C$37+הנחות!$C$38)+סיכום!$C$6*(1+C$4)*הנחות!$C$44+עלויות!$D$21+עלויות!$D$25+עלויות!$D$26)))/(עלויות!$D$37+עלויות!$D$11*(1+$A5)+(עלויות!$D$15+עלויות!$D$11*(1+$A5)*(הנחות!$C$36+הנחות!$C$39+הנחות!$C$43+הנחות!$C$45)+עלויות!$D$11*(1+$A5)*הנחות!$C$40*הנחות!$C$41+סיכום!$C$7*(1+C$4)*(הנחות!$C$37+הנחות!$C$38)+סיכום!$C$6*(1+C$4)*הנחות!$C$44+עלויות!$D$21+עלויות!$D$25+עלויות!$D$26)),0) -> 0.23859486 | D5: =IFERROR((סיכום!$C$7*(1+D$4)-(עלויות!$D$37+עלויות!$D$11*(1+$A5)+(עלויות!$D$15+עלויות!$D$11*(1+$A5)*(הנחות!$C$36+הנחות!$C$39+הנחות!$C$43+הנחות!$C$45)+עלויות!$D$11*(1+$A5)*הנחות!$C$40*הנחות!$C$41+סיכום!$C$7*(1+D$4)*(הנחות!$C$37+הנחות!$C$38)+סיכום!$C$6*(1+D$4)*הנחות!$C$44+עלויות!$D$21+עלויות!$D$25+עלויות!$D$26)))/(עלויות!$D$37+עלויות!$D$11*(1+$A5)+(עלויות!$D$15+עלויות!$D$11*(1+$A5)*(הנחות!$C$36+הנחות!$C$39+הנחות!$C$43+הנחות!$C$45)+עלויות!$D$11*(1+$A5)*הנחות!$C$40*הנחות!$C$41+סיכום!$C$7*(1+D$4)*(הנחות!$C$37+הנחות!$C$38)+סיכום!$C$6*(1+D$4)*הנחות!$C$44+עלויות!$D$21+עלויות!$D$25+עלויות!$D$26)),0) -> 0.27039312 | E5: =IFERROR((סיכום!$C$7*(1+E$4)-(עלויות!$D$37+עלויות!$D$11*(1+$A5)+(עלויות!$D$15+עלויות!$D$11*(1+$A5)*(הנחות!$C$36+הנחות!$C$39+הנחות!$C$43+הנחות!$C$45)+עלויות!$D$11*(1+$A5)*הנחות!$C$40*הנחות!$C$41+סיכום!$C$7*(1+E$4)*(הנחות!$C$37+הנחות!$C$38)+סיכום!$C$6*(1+E$4)*הנחות!$C$44+עלויות!$D$21+עלויות!$D$25+עלויות!$D$26)))/(עלויות!$D$37+עלויות!$D$11*(1+$A5)+(עלויות!$D$15+עלויות!$D$11*(1+$A5)*(הנחות!$C$36+הנחות!$C$39+הנחות!$C$43+הנחות!$C$45)+עלויות!$D$11*(1+$A5)*הנחות!$C$40*הנחות!$C$41+סיכום!$C$7*(1+E$4)*(הנחות!$C$37+הנחות!$C$38)+סיכום!$C$6*(1+E$4)*הנחות!$C$44+עלויות!$D$21+עלויות!$D$25+עלויות!$D$26)),0) -> 0.30210765 | F5: =IFERROR((סיכום!$C$7*(1+F$4)-(עלויות!$D$37+עלויות!$D$11*(1+$A5)+(עלויות!$D$15+עלויות!$D$11*(1+$A5)*(הנחות!$C$36+הנחות!$C$39+הנחות!$C$43+הנחות!$C$45)+עלויות!$D$11*(1+$A5)*הנחות!$C$40*הנחות!$C$41+סיכום!$C$7*(1+F$4)*(הנחות!$C$37+הנחות!$C$38)+סיכום!$C$6*(1+F$4)*הנחות!$C$44+עלויות!$D$21+עלויות!$D$25+עלויות!$D$26)))/(עלויות!$D$37+עלויות!$D$11*(1+$A5)+(עלויות!$D$15+עלויות!$D$11*(1+$A5)*(הנחות!$C$36+הנחות!$C$39+הנחות!$C$43+הנחות!$C$45)+עלויות!$D$11*(1+$A5)*הנחות!$C$40*הנחות!$C$41+סיכום!$C$7*(1+F$4)*(הנחות!$C$37+הנחות!$C$38)+סיכום!$C$6*(1+F$4)*הנחות!$C$44+עלויות!$D$21+עלויות!$D$25+עלויות!$D$26)),0) -> 0.33373876 | G5: =IFERROR((סיכום!$C$7*(1+G$4)-(עלויות!$D$37+עלויות!$D$11*(1+$A5)+(עלויות!$D$15+עלויות!$D$11*(1+$A5)*(הנחות!$C$36+הנחות!$C$39+הנחות!$C$43+הנחות!$C$45)+עלויות!$D$11*(1+$A5)*הנחות!$C$40*הנחות!$C$41+סיכום!$C$7*(1+G$4)*(הנחות!$C$37+הנחות!$C$38)+סיכום!$C$6*(1+G$4)*הנחות!$C$44+עלויות!$D$21+עלויות!$D$25+עלויות!$D$26)))/(עלויות!$D$37+עלויות!$D$11*(1+$A5)+(עלויות!$D$15+עלויות!$D$11*(1+$A5)*(הנחות!$C$36+הנחות!$C$39+הנחות!$C$43+הנחות!$C$45)+עלויות!$D$11*(1+$A5)*הנחות!$C$40*הנחות!$C$41+סיכום!$C$7*(1+G$4)*(הנחות!$C$37+הנחות!$C$38)+סיכום!$C$6*(1+G$4)*הנחות!$C$44+עלויות!$D$21+עלויות!$D$25+עלויות!$D$26)),0) -> 0.36528678 | H5: =IFERROR((סיכום!$C$7*(1+H$4)-(עלויות!$D$37+עלויות!$D$11*(1+$A5)+(עלויות!$D$15+עלויות!$D$11*(1+$A5)*(הנחות!$C$36+הנחות!$C$39+הנחות!$C$43+הנחות!$C$45)+עלויות!$D$11*(1+$A5)*הנחות!$C$40*הנחות!$C$41+סיכום!$C$7*(1+H$4)*(הנחות!$C$37+הנחות!$C$38)+סיכום!$C$6*(1+H$4)*הנחות!$C$44+עלויות!$D$21+עלויות!$D$25+עלויות!$D$26)))/(עלויות!$D$37+עלויות!$D$11*(1+$A5)+(עלויות!$D$15+עלויות!$D$11*(1+$A5)*(הנחות!$C$36+הנחות!$C$39+הנחות!$C$43+הנחות!$C$45)+עלויות!$D$11*(1+$A5)*הנחות!$C$40*הנחות!$C$41+סיכום!$C$7*(1+H$4)*(הנחות!$C$37+הנחות!$C$38)+סיכום!$C$6*(1+H$4)*הנחות!$C$44+עלויות!$D$21+עלויות!$D$25+עלויות!$D$26)),0) -> 0.39675205 | I5: =IFERROR((סיכום!$C$7*(1+I$4)-(עלויות!$D$37+עלויות!$D$11*(1+$A5)+(עלויות!$D$15+עלויות!$D$11*(1+$A5)*(הנחות!$C$36+הנחות!$C$39+הנחות!$C$43+הנחות!$C$45)+עלויות!$D$11*(1+$A5)*הנחות!$C$40*הנחות!$C$41+סיכום!$C$7*(1+I$4)*(הנחות!$C$37+הנחות!$C$38)+סיכום!$C$6*(1+I$4)*הנחות!$C$44+עלויות!$D$21+עלויות!$D$25+עלויות!$D$26)))/(עלויות!$D$37+עלויות!$D$11*(1+$A5)+(עלויות!$D$15+עלויות!$D$11*(1+$A5)*(הנחות!$C$36+הנחות!$C$39+הנחות!$C$43+הנחות!$C$45)+עלויות!$D$11*(1+$A5)*הנחות!$C$40*הנחות!$C$41+סיכום!$C$7*(1+I$4)*(הנחות!$C$37+הנחות!$C$38)+סיכום!$C$6*(1+I$4)*הנחות!$C$44+עלויות!$D$21+עלויות!$D$25+עלויות!$D$26)),0) -> 0.42813489 | J5: =IFERROR((סיכום!$C$7*(1+J$4)-(עלויות!$D$37+עלויות!$D$11*(1+$A5)+(עלויות!$D$15+עלויות!$D$11*(1+$A5)*(הנחות!$C$36+הנחות!$C$39+הנחות!$C$43+הנחות!$C$45)+עלויות!$D$11*(1+$A5)*הנחות!$C$40*הנחות!$C$41+סיכום!$C$7*(1+J$4)*(הנחות!$C$37+הנחות!$C$38)+סיכום!$C$6*(1+J$4)*הנחות!$C$44+עלויות!$D$21+עלויות!$D$25+עלויות!$D$26)))/(עלויות!$D$37+עלויות!$D$11*(1+$A5)+(עלויות!$D$15+עלויות!$D$11*(1+$A5)*(הנחות!$C$36+הנחות!$C$39+הנחות!$C$43+הנחות!$C$45)+עלויות!$D$11*(1+$A5)*הנחות!$C$40*הנחות!$C$41+סיכום!$C$7*(1+J$4)*(הנחות!$C$37+הנחות!$C$38)+סיכום!$C$6*(1+J$4)*הנחות!$C$44+עלויות!$D$21+עלויות!$D$25+עלויות!$D$26)),0) -> 0.45943562
A6: -0.05 | B6: =IFERROR((סיכום!$C$7*(1+B$4)-(עלויות!$D$37+עלויות!$D$11*(1+$A6)+(עלויות!$D$15+עלויות!$D$11*(1+$A6)*(הנחות!$C$36+הנחות!$C$39+הנחות!$C$43+הנחות!$C$45)+עלויות!$D$11*(1+$A6)*הנחות!$C$40*הנחות!$C$41+סיכום!$C$7*(1+B$4)*(הנחות!$C$37+הנחות!$C$38)+סיכום!$C$6*(1+B$4)*הנחות!$C$44+עלויות!$D$21+עלויות!$D$25+עלויות!$D$26)))/(עלויות!$D$37+עלויות!$D$11*(1+$A6)+(עלויות!$D$15+עלויות!$D$11*(1+$A6)*(הנחות!$C$36+הנחות!$C$39+הנחות!$C$43+הנחות!$C$45)+עלויות!$D$11*(1+$A6)*הנחות!$C$40*הנחות!$C$41+סיכום!$C$7*(1+B$4)*(הנחות!$C$37+הנחות!$C$38)+סיכום!$C$6*(1+B$4)*הנחות!$C$44+עלויות!$D$21+עלויות!$D$25+עלויות!$D$26)),0) -> 0.16602329 | C6: =IFERROR((סיכום!$C$7*(1+C$4)-(עלויות!$D$37+עלויות!$D$11*(1+$A6)+(עלויות!$D$15+עלויות!$D$11*(1+$A6)*(הנחות!$C$36+הנחות!$C$39+הנחות!$C$43+הנחות!$C$45)+עלויות!$D$11*(1+$A6)*הנחות!$C$40*הנחות!$C$41+סיכום!$C$7*(1+C$4)*(הנחות!$C$37+הנחות!$C$38)+סיכום!$C$6*(1+C$4)*הנחות!$C$44+עלויות!$D$21+עלויות!$D$25+עלויות!$D$26)))/(עלויות!$D$37+עלויות!$D$11*(1+$A6)+(עלויות!$D$15+עלויות!$D$11*(1+$A6)*(הנחות!$C$36+הנחות!$C$39+הנחות!$C$43+הנחות!$C$45)+עלויות!$D$11*(1+$A6)*הנחות!$C$40*הנחות!$C$41+סיכום!$C$7*(1+C$4)*(הנחות!$C$37+הנחות!$C$38)+סיכום!$C$6*(1+C$4)*הנחות!$C$44+עלויות!$D$21+עלויות!$D$25+עלויות!$D$26)),0) -> 0.19688388 | D6: =IFERROR((סיכום!$C$7*(1+D$4)-(עלויות!$D$37+עלויות!$D$11*(1+$A6)+(עלויות!$D$15+עלויות!$D$11*(1+$A6)*(הנחות!$C$36+הנחות!$C$39+הנחות!$C$43+הנחות!$C$45)+עלויות!$D$11*(1+$A6)*הנחות!$C$40*הנחות!$C$41+סיכום!$C$7*(1+D$4)*(הנחות!$C$37+הנחות!$C$38)+סיכום!$C$6*(1+D$4)*הנחות!$C$44+עלויות!$D$21+עלויות!$D$25+עלויות!$D$26)))/(עלויות!$D$37+עלויות!$D$11*(1+$A6)+(עלויות!$D$15+עלויות!$D$11*(1+$A6)*(הנחות!$C$36+הנחות!$C$39+הנחות!$C$43+הנחות!$C$45)+עלויות!$D$11*(1+$A6)*הנחות!$C$40*הנחות!$C$41+סיכום!$C$7*(1+D$4)*(הנחות!$C$37+הנחות!$C$38)+סיכום!$C$6*(1+D$4)*הנחות!$C$44+עלויות!$D$21+עלויות!$D$25+עלויות!$D$26)),0) -> 0.22766582 | E6: =IFERROR((סיכום!$C$7*(1+E$4)-(עלויות!$D$37+עלויות!$D$11*(1+$A6)+(עלויות!$D$15+עלויות!$D$11*(1+$A6)*(הנחות!$C$36+הנחות!$C$39+הנחות!$C$43+הנחות!$C$45)+עלויות!$D$11*(1+$A6)*הנחות!$C$40*הנחות!$C$41+סיכום!$C$7*(1+E$4)*(הנחות!$C$37+הנחות!$C$38)+סיכום!$C$6*(1+E$4)*הנחות!$C$44+עלויות!$D$21+עלויות!$D$25+עלויות!$D$26)))/(עלויות!$D$37+עלויות!$D$11*(1+$A6)+(עלויות!$D$15+עלויות!$D$11*(1+$A6)*(הנחות!$C$36+הנחות!$C$39+הנחות!$C$43+הנחות!$C$45)+עלויות!$D$11*(1+$A6)*הנחות!$C$40*הנחות!$C$41+סיכום!$C$7*(1+E$4)*(הנחות!$C$37+הנחות!$C$38)+סיכום!$C$6*(1+E$4)*הנחות!$C$44+עלויות!$D$21+עלויות!$D$25+עלויות!$D$26)),0) -> 0.25836941 | F6: =IFERROR((סיכום!$C$7*(1+F$4)-(עלויות!$D$37+עלויות!$D$11*(1+$A6)+(עלויות!$D$15+עלויות!$D$11*(1+$A6)*(הנחות!$C$36+הנחות!$C$39+הנחות!$C$43+הנחות!$C$45)+עלויות!$D$11*(1+$A6)*הנחות!$C$40*הנחות!$C$41+סיכום!$C$7*(1+F$4)*(הנחות!$C$37+הנחות!$C$38)+סיכום!$C$6*(1+F$4)*הנחות!$C$44+עלויות!$D$21+עלויות!$D$25+עלויות!$D$26)))/(עלויות!$D$37+עלויות!$D$11*(1+$A6)+(עלויות!$D$15+עלויות!$D$11*(1+$A6)*(הנחות!$C$36+הנחות!$C$39+הנחות!$C$43+הנחות!$C$45)+עלויות!$D$11*(1+$A6)*הנחות!$C$40*הנחות!$C$41+סיכום!$C$7*(1+F$4)*(הנחות!$C$37+הנחות!$C$38)+סיכום!$C$6*(1+F$4)*הנחות!$C$44+עלויות!$D$21+עלויות!$D$25+עלויות!$D$26)),0) -> 0.28899497 | G6: =IFERROR((סיכום!$C$7*(1+G$4)-(עלויות!$D$37+עלויות!$D$11*(1+$A6)+(עלויות!$D$15+עלויות!$D$11*(1+$A6)*(הנחות!$C$36+הנחות!$C$39+הנחות!$C$43+הנחות!$C$45)+עלויות!$D$11*(1+$A6)*הנחות!$C$40*הנחות!$C$41+סיכום!$C$7*(1+G$4)*(הנחות!$C$37+הנחות!$C$38)+סיכום!$C$6*(1+G$4)*הנחות!$C$44+עלויות!$D$21+עלויות!$D$25+עלויות!$D$26)))/(עלויות!$D$37+עלויות!$D$11*(1+$A6)+(עלויות!$D$15+עלויות!$D$11*(1+$A6)*(הנחות!$C$36+הנחות!$C$39+הנחות!$C$43+הנחות!$C$45)+עלויות!$D$11*(1+$A6)*הנחות!$C$40*הנחות!$C$41+סיכום!$C$7*(1+G$4)*(הנחות!$C$37+הנחות!$C$38)+סיכום!$C$6*(1+G$4)*הנחות!$C$44+עלויות!$D$21+עלויות!$D$25+עלויות!$D$26)),0) -> 0.31954277 | H6: =IFERROR((סיכום!$C$7*(1+H$4)-(עלויות!$D$37+עלויות!$D$11*(1+$A6)+(עלויות!$D$15+עלויות!$D$11*(1+$A6)*(הנחות!$C$36+הנחות!$C$39+הנחות!$C$43+הנחות!$C$45)+עלויות!$D$11*(1+$A6)*הנחות!$C$40*הנחות!$C$41+סיכום!$C$7*(1+H$4)*(הנחות!$C$37+הנחות!$C$38)+סיכום!$C$6*(1+H$4)*הנחות!$C$44+עלויות!$D$21+עלויות!$D$25+עלויות!$D$26)))/(עלויות!$D$37+עלויות!$D$11*(1+$A6)+(עלויות!$D$15+עלויות!$D$11*(1+$A6)*(הנחות!$C$36+הנחות!$C$39+הנחות!$C$43+הנחות!$C$45)+עלויות!$D$11*(1+$A6)*הנחות!$C$40*הנחות!$C$41+סיכום!$C$7*(1+H$4)*(הנחות!$C$37+הנחות!$C$38)+סיכום!$C$6*(1+H$4)*הנחות!$C$44+עלויות!$D$21+עלויות!$D$25+עלויות!$D$26)),0) -> 0.35001312 | I6: =IFERROR((סיכום!$C$7*(1+I$4)-(עלויות!$D$37+עלויות!$D$11*(1+$A6)+(עלויות!$D$15+עלויות!$D$11*(1+$A6)*(הנחות!$C$36+הנחות!$C$39+הנחות!$C$43+הנחות!$C$45)+עלויות!$D$11*(1+$A6)*הנחות!$C$40*הנחות!$C$41+סיכום!$C$7*(1+I$4)*(הנחות!$C$37+הנחות!$C$38)+סיכום!$C$6*(1+I$4)*הנחות!$C$44+עלויות!$D$21+עלויות!$D$25+עלויות!$D$26)))/(עלויות!$D$37+עלויות!$D$11*(1+$A6)+(עלויות!$D$15+עלויות!$D$11*(1+$A6)*(הנחות!$C$36+הנחות!$C$39+הנחות!$C$43+הנחות!$C$45)+עלויות!$D$11*(1+$A6)*הנחות!$C$40*הנחות!$C$41+סיכום!$C$7*(1+I$4)*(הנחות!$C$37+הנחות!$C$38)+סיכום!$C$6*(1+I$4)*הנחות!$C$44+עלויות!$D$21+עלויות!$D$25+עלויות!$D$26)),0) -> 0.38040631 | J6: =IFERROR((סיכום!$C$7*(1+J$4)-(עלויות!$D$37+עלויות!$D$11*(1+$A6)+(עלויות!$D$15+עלויות!$D$11*(1+$A6)*(הנחות!$C$36+הנחות!$C$39+הנחות!$C$43+הנחות!$C$45)+עלויות!$D$11*(1+$A6)*הנחות!$C$40*הנחות!$C$41+סיכום!$C$7*(1+J$4)*(הנחות!$C$37+הנחות!$C$38)+סיכום!$C$6*(1+J$4)*הנחות!$C$44+עלויות!$D$21+עלויות!$D$25+עלויות!$D$26)))/(עלויות!$D$37+עלויות!$D$11*(1+$A6)+(עלויות!$D$15+עלויות!$D$11*(1+$A6)*(הנחות!$C$36+הנחות!$C$39+הנחות!$C$43+הנחות!$C$45)+עלויות!$D$11*(1+$A6)*הנחות!$C$40*הנחות!$C$41+סיכום!$C$7*(1+J$4)*(הנחות!$C$37+הנחות!$C$38)+סיכום!$C$6*(1+J$4)*הנחות!$C$44+עלויות!$D$21+עלויות!$D$25+עלויות!$D$26)),0) -> 0.41072264
A7: 0 | B7: =IFERROR((סיכום!$C$7*(1+B$4)-(עלויות!$D$37+עלויות!$D$11*(1+$A7)+(עלויות!$D$15+עלויות!$D$11*(1+$A7)*(הנחות!$C$36+הנחות!$C$39+הנחות!$C$43+הנחות!$C$45)+עלויות!$D$11*(1+$A7)*הנחות!$C$40*הנחות!$C$41+סיכום!$C$7*(1+B$4)*(הנחות!$C$37+הנחות!$C$38)+סיכום!$C$6*(1+B$4)*הנחות!$C$44+עלויות!$D$21+עלויות!$D$25+עלויות!$D$26)))/(עלויות!$D$37+עלויות!$D$11*(1+$A7)+(עלויות!$D$15+עלויות!$D$11*(1+$A7)*(הנחות!$C$36+הנחות!$C$39+הנחות!$C$43+הנחות!$C$45)+עלויות!$D$11*(1+$A7)*הנחות!$C$40*הנחות!$C$41+סיכום!$C$7*(1+B$4)*(הנחות!$C$37+הנחות!$C$38)+סיכום!$C$6*(1+B$4)*הנחות!$C$44+עלויות!$D$21+עלויות!$D$25+עלויות!$D$26)),0) -> 0.12798857 | C7: =IFERROR((סיכום!$C$7*(1+C$4)-(עלויות!$D$37+עלויות!$D$11*(1+$A7)+(עלויות!$D$15+עלויות!$D$11*(1+$A7)*(הנחות!$C$36+הנחות!$C$39+הנחות!$C$43+הנחות!$C$45)+עלויות!$D$11*(1+$A7)*הנחות!$C$40*הנחות!$C$41+סיכום!$C$7*(1+C$4)*(הנחות!$C$37+הנחות!$C$38)+סיכום!$C$6*(1+C$4)*הנחות!$C$44+עלויות!$D$21+עלויות!$D$25+עלויות!$D$26)))/(עלויות!$D$37+עלויות!$D$11*(1+$A7)+(עלויות!$D$15+עלויות!$D$11*(1+$A7)*(הנחות!$C$36+הנחות!$C$39+הנחות!$C$43+הנחות!$C$45)+עלויות!$D$11*(1+$A7)*הנחות!$C$40*הנחות!$C$41+סיכום!$C$7*(1+C$4)*(הנחות!$C$37+הנחות!$C$38)+סיכום!$C$6*(1+C$4)*הנחות!$C$44+עלויות!$D$21+עלויות!$D$25+עלויות!$D$26)),0) -> 0.1578907 | D7: =IFERROR((סיכום!$C$7*(1+D$4)-(עלויות!$D$37+עלויות!$D$11*(1+$A7)+(עלויות!$D$15+עלויות!$D$11*(1+$A7)*(הנחות!$C$36+הנחות!$C$39+הנחות!$C$43+הנחות!$C$45)+עלויות!$D$11*(1+$A7)*הנחות!$C$40*הנחות!$C$41+סיכום!$C$7*(1+D$4)*(הנחות!$C$37+הנחות!$C$38)+סיכום!$C$6*(1+D$4)*הנחות!$C$44+עלויות!$D$21+עלויות!$D$25+עלויות!$D$26)))/(עלויות!$D$37+עלויות!$D$11*(1+$A7)+(עלויות!$D$15+עלויות!$D$11*(1+$A7)*(הנחות!$C$36+הנחות!$C$39+הנחות!$C$43+הנחות!$C$45)+עלויות!$D$11*(1+$A7)*הנחות!$C$40*הנחות!$C$41+סיכום!$C$7*(1+D$4)*(הנחות!$C$37+הנחות!$C$38)+סיכום!$C$6*(1+D$4)*הנחות!$C$44+עלויות!$D$21+עלויות!$D$25+עלויות!$D$26)),0) -> 0.1877191 | E7: =IFERROR((סיכום!$C$7*(1+E$4)-(עלויות!$D$37+עלויות!$D$11*(1+$A7)+(עלויות!$D$15+עלויות!$D$11*(1+$A7)*(הנחות!$C$36+הנחות!$C$39+הנחות!$C$43+הנחות!$C$45)+עלויות!$D$11*(1+$A7)*הנחות!$C$40*הנחות!$C$41+סיכום!$C$7*(1+E$4)*(הנחות!$C$37+הנחות!$C$38)+סיכום!$C$6*(1+E$4)*הנחות!$C$44+עלויות!$D$21+עלויות!$D$25+עלויות!$D$26)))/(עלויות!$D$37+עלויות!$D$11*(1+$A7)+(עלויות!$D$15+עלויות!$D$11*(1+$A7)*(הנחות!$C$36+הנחות!$C$39+הנחות!$C$43+הנחות!$C$45)+עלויות!$D$11*(1+$A7)*הנחות!$C$40*הנחות!$C$41+סיכום!$C$7*(1+E$4)*(הנחות!$C$37+הנחות!$C$38)+סיכום!$C$6*(1+E$4)*הנחות!$C$44+עלויות!$D$21+עלויות!$D$25+עלויות!$D$26)),0) -> 0.21747405 | F7: =IFERROR((סיכום!$C$7*(1+F$4)-(עלויות!$D$37+עלויות!$D$11*(1+$A7)+(עלויות!$D$15+עלויות!$D$11*(1+$A7)*(הנחות!$C$36+הנחות!$C$39+הנחות!$C$43+הנחות!$C$45)+עלויות!$D$11*(1+$A7)*הנחות!$C$40*הנחות!$C$41+סיכום!$C$7*(1+F$4)*(הנחות!$C$37+הנחות!$C$38)+סיכום!$C$6*(1+F$4)*הנחות!$C$44+עלויות!$D$21+עלויות!$D$25+עלויות!$D$26)))/(עלויות!$D$37+עלויות!$D$11*(1+$A7)+(עלויות!$D$15+עלויות!$D$11*(1+$A7)*(הנחות!$C$36+הנחות!$C$39+הנחות!$C$43+הנחות!$C$45)+עלויות!$D$11*(1+$A7)*הנחות!$C$40*הנחות!$C$41+סיכום!$C$7*(1+F$4)*(הנחות!$C$37+הנחות!$C$38)+סיכום!$C$6*(1+F$4)*הנחות!$C$44+עלויות!$D$21+עלויות!$D$25+עלויות!$D$26)),0) -> 0.24715583 | G7: =IFERROR((סיכום!$C$7*(1+G$4)-(עלויות!$D$37+עלויות!$D$11*(1+$A7)+(עלויות!$D$15+עלויות!$D$11*(1+$A7)*(הנחות!$C$36+הנחות!$C$39+הנחות!$C$43+הנחות!$C$45)+עלויות!$D$11*(1+$A7)*הנחות!$C$40*הנחות!$C$41+סיכום!$C$7*(1+G$4)*(הנחות!$C$37+הנחות!$C$38)+סיכום!$C$6*(1+G$4)*הנחות!$C$44+עלויות!$D$21+עלויות!$D$25+עלויות!$D$26)))/(עלויות!$D$37+עלויות!$D$11*(1+$A7)+(עלויות!$D$15+עלויות!$D$11*(1+$A7)*(הנחות!$C$36+הנחות!$C$39+הנחות!$C$43+הנחות!$C$45)+עלויות!$D$11*(1+$A7)*הנחות!$C$40*הנחות!$C$41+סיכום!$C$7*(1+G$4)*(הנחות!$C$37+הנחות!$C$38)+סיכום!$C$6*(1+G$4)*הנחות!$C$44+עלויות!$D$21+עלויות!$D$25+עלויות!$D$26)),0) -> 0.27676469 | H7: =IFERROR((סיכום!$C$7*(1+H$4)-(עלויות!$D$37+עלויות!$D$11*(1+$A7)+(עלויות!$D$15+עלויות!$D$11*(1+$A7)*(הנחות!$C$36+הנחות!$C$39+הנחות!$C$43+הנחות!$C$45)+עלויות!$D$11*(1+$A7)*הנחות!$C$40*הנחות!$C$41+סיכום!$C$7*(1+H$4)*(הנחות!$C$37+הנחות!$C$38)+סיכום!$C$6*(1+H$4)*הנחות!$C$44+עלויות!$D$21+עלויות!$D$25+עלויות!$D$26)))/(עלויות!$D$37+עלויות!$D$11*(1+$A7)+(עלויות!$D$15+עלויות!$D$11*(1+$A7)*(הנחות!$C$36+הנחות!$C$39+הנחות!$C$43+הנחות!$C$45)+עלויות!$D$11*(1+$A7)*הנחות!$C$40*הנחות!$C$41+סיכום!$C$7*(1+H$4)*(הנחות!$C$37+הנחות!$C$38)+סיכום!$C$6*(1+H$4)*הנחות!$C$44+עלויות!$D$21+עלויות!$D$25+עלויות!$D$26)),0) -> 0.30630091 | I7: =IFERROR((סיכום!$C$7*(1+I$4)-(עלויות!$D$37+עלויות!$D$11*(1+$A7)+(עלויות!$D$15+עלויות!$D$11*(1+$A7)*(הנחות!$C$36+הנחות!$C$39+הנחות!$C$43+הנחות!$C$45)+עלויות!$D$11*(1+$A7)*הנחות!$C$40*הנחות!$C$41+סיכום!$C$7*(1+I$4)*(הנחות!$C$37+הנחות!$C$38)+סיכום!$C$6*(1+I$4)*הנחות!$C$44+עלויות!$D$21+עלויות!$D$25+עלויות!$D$26)))/(עלויות!$D$37+עלויות!$D$11*(1+$A7)+(עלויות!$D$15+עלויות!$D$11*(1+$A7)*(הנחות!$C$36+הנחות!$C$39+הנחות!$C$43+הנחות!$C$45)+עלויות!$D$11*(1+$A7)*הנחות!$C$40*הנחות!$C$41+סיכום!$C$7*(1+I$4)*(הנחות!$C$37+הנחות!$C$38)+סיכום!$C$6*(1+I$4)*הנחות!$C$44+עלויות!$D$21+עלויות!$D$25+עלויות!$D$26)),0) -> 0.33576476 | J7: =IFERROR((סיכום!$C$7*(1+J$4)-(עלויות!$D$37+עלויות!$D$11*(1+$A7)+(עלויות!$D$15+עלויות!$D$11*(1+$A7)*(הנחות!$C$36+הנחות!$C$39+הנחות!$C$43+הנחות!$C$45)+עלויות!$D$11*(1+$A7)*הנחות!$C$40*הנחות!$C$41+סיכום!$C$7*(1+J$4)*(הנחות!$C$37+הנחות!$C$38)+סיכום!$C$6*(1+J$4)*הנחות!$C$44+עלויות!$D$21+עלויות!$D$25+עלויות!$D$26)))/(עלויות!$D$37+עלויות!$D$11*(1+$A7)+(עלויות!$D$15+עלויות!$D$11*(1+$A7)*(הנחות!$C$36+הנחות!$C$39+הנחות!$C$43+הנחות!$C$45)+עלויות!$D$11*(1+$A7)*הנחות!$C$40*הנחות!$C$41+סיכום!$C$7*(1+J$4)*(הנחות!$C$37+הנחות!$C$38)+סיכום!$C$6*(1+J$4)*הנחות!$C$44+עלויות!$D$21+עלויות!$D$25+עלויות!$D$26)),0) -> 0.3651565
A8: 0.05 | B8: =IFERROR((סיכום!$C$7*(1+B$4)-(עלויות!$D$37+עלויות!$D$11*(1+$A8)+(עלויות!$D$15+עלויות!$D$11*(1+$A8)*(הנחות!$C$36+הנחות!$C$39+הנחות!$C$43+הנחות!$C$45)+עלויות!$D$11*(1+$A8)*הנחות!$C$40*הנחות!$C$41+סיכום!$C$7*(1+B$4)*(הנחות!$C$37+הנחות!$C$38)+סיכום!$C$6*(1+B$4)*הנחות!$C$44+עלויות!$D$21+עלויות!$D$25+עלויות!$D$26)))/(עלויות!$D$37+עלויות!$D$11*(1+$A8)+(עלויות!$D$15+עלויות!$D$11*(1+$A8)*(הנחות!$C$36+הנחות!$C$39+הנחות!$C$43+הנחות!$C$45)+עלויות!$D$11*(1+$A8)*הנחות!$C$40*הנחות!$C$41+סיכום!$C$7*(1+B$4)*(הנחות!$C$37+הנחות!$C$38)+סיכום!$C$6*(1+B$4)*הנחות!$C$44+עלויות!$D$21+עלויות!$D$25+עלויות!$D$26)),0) -> 0.092356794 | C8: =IFERROR((סיכום!$C$7*(1+C$4)-(עלויות!$D$37+עלויות!$D$11*(1+$A8)+(עלויות!$D$15+עלויות!$D$11*(1+$A8)*(הנחות!$C$36+הנחות!$C$39+הנחות!$C$43+הנחות!$C$45)+עלויות!$D$11*(1+$A8)*הנחות!$C$40*הנחות!$C$41+סיכום!$C$7*(1+C$4)*(הנחות!$C$37+הנחות!$C$38)+סיכום!$C$6*(1+C$4)*הנחות!$C$44+עלויות!$D$21+עלויות!$D$25+עלויות!$D$26)))/(עלויות!$D$37+עלויות!$D$11*(1+$A8)+(עלויות!$D$15+עלויות!$D$11*(1+$A8)*(הנחות!$C$36+הנחות!$C$39+הנחות!$C$43+הנחות!$C$45)+עלויות!$D$11*(1+$A8)*הנחות!$C$40*הנחות!$C$41+סיכום!$C$7*(1+C$4)*(הנחות!$C$37+הנחות!$C$38)+סיכום!$C$6*(1+C$4)*הנחות!$C$44+עלויות!$D$21+עלויות!$D$25+עלויות!$D$26)),0) -> 0.12135807 | D8: =IFERROR((סיכום!$C$7*(1+D$4)-(עלויות!$D$37+עלויות!$D$11*(1+$A8)+(עלויות!$D$15+עלויות!$D$11*(1+$A8)*(הנחות!$C$36+הנחות!$C$39+הנחות!$C$43+הנחות!$C$45)+עלויות!$D$11*(1+$A8)*הנחות!$C$40*הנחות!$C$41+סיכום!$C$7*(1+D$4)*(הנחות!$C$37+הנחות!$C$38)+סיכום!$C$6*(1+D$4)*הנחות!$C$44+עלויות!$D$21+עלויות!$D$25+עלויות!$D$26)))/(עלויות!$D$37+עלויות!$D$11*(1+$A8)+(עלויות!$D$15+עלויות!$D$11*(1+$A8)*(הנחות!$C$36+הנחות!$C$39+הנחות!$C$43+הנחות!$C$45)+עלויות!$D$11*(1+$A8)*הנחות!$C$40*הנחות!$C$41+סיכום!$C$7*(1+D$4)*(הנחות!$C$37+הנחות!$C$38)+סיכום!$C$6*(1+D$4)*הנחות!$C$44+עלויות!$D$21+עלויות!$D$25+עלויות!$D$26)),0) -> 0.15029009 | E8: =IFERROR((סיכום!$C$7*(1+E$4)-(עלויות!$D$37+עלויות!$D$11*(1+$A8)+(עלויות!$D$15+עלויות!$D$11*(1+$A8)*(הנחות!$C$36+הנחות!$C$39+הנחות!$C$43+הנחות!$C$45)+עלויות!$D$11*(1+$A8)*הנחות!$C$40*הנחות!$C$41+סיכום!$C$7*(1+E$4)*(הנחות!$C$37+הנחות!$C$38)+סיכום!$C$6*(1+E$4)*הנחות!$C$44+עלויות!$D$21+עלויות!$D$25+עלויות!$D$26)))/(עלויות!$D$37+עלויות!$D$11*(1+$A8)+(עלויות!$D$15+עלויות!$D$11*(1+$A8)*(הנחות!$C$36+הנחות!$C$39+הנחות!$C$43+הנחות!$C$45)+עלויות!$D$11*(1+$A8)*הנחות!$C$40*הנחות!$C$41+סיכום!$C$7*(1+E$4)*(הנחות!$C$37+הנחות!$C$38)+סיכום!$C$6*(1+E$4)*הנחות!$C$44+עלויות!$D$21+עלויות!$D$25+עלויות!$D$26)),0) -> 0.17915312 | F8: =IFERROR((סיכום!$C$7*(1+F$4)-(עלויות!$D$37+עלויות!$D$11*(1+$A8)+(עלויות!$D$15+עלויות!$D$11*(1+$A8)*(הנחות!$C$36+הנחות!$C$39+הנחות!$C$43+הנחות!$C$45)+עלויות!$D$11*(1+$A8)*הנחות!$C$40*הנחות!$C$41+סיכום!$C$7*(1+F$4)*(הנחות!$C$37+הנחות!$C$38)+סיכום!$C$6*(1+F$4)*הנחות!$C$44+עלויות!$D$21+עלויות!$D$25+עלויות!$D$26)))/(עלויות!$D$37+עלויות!$D$11*(1+$A8)+(עלויות!$D$15+עלויות!$D$11*(1+$A8)*(הנחות!$C$36+הנחות!$C$39+הנחות!$C$43+הנחות!$C$45)+עלויות!$D$11*(1+$A8)*הנחות!$C$40*הנחות!$C$41+סיכום!$C$7*(1+F$4)*(הנחות!$C$37+הנחות!$C$38)+סיכום!$C$6*(1+F$4)*הנחות!$C$44+עלויות!$D$21+עלויות!$D$25+עלויות!$D$26)),0) -> 0.20794739 | G8: =IFERROR((סיכום!$C$7*(1+G$4)-(עלויות!$D$37+עלויות!$D$11*(1+$A8)+(עלויות!$D$15+עלויות!$D$11*(1+$A8)*(הנחות!$C$36+הנחות!$C$39+הנחות!$C$43+הנחות!$C$45)+עלויות!$D$11*(1+$A8)*הנחות!$C$40*הנחות!$C$41+סיכום!$C$7*(1+G$4)*(הנחות!$C$37+הנחות!$C$38)+סיכום!$C$6*(1+G$4)*הנחות!$C$44+עלויות!$D$21+עלויות!$D$25+עלויות!$D$26)))/(עלויות!$D$37+עלויות!$D$11*(1+$A8)+(עלויות!$D$15+עלויות!$D$11*(1+$A8)*(הנחות!$C$36+הנחות!$C$39+הנחות!$C$43+הנחות!$C$45)+עלויות!$D$11*(1+$A8)*הנחות!$C$40*הנחות!$C$41+סיכום!$C$7*(1+G$4)*(הנחות!$C$37+הנחות!$C$38)+סיכום!$C$6*(1+G$4)*הנחות!$C$44+עלויות!$D$21+עלויות!$D$25+עלויות!$D$26)),0) -> 0.23667315 | H8: =IFERROR((סיכום!$C$7*(1+H$4)-(עלויות!$D$37+עלויות!$D$11*(1+$A8)+(עלויות!$D$15+עלויות!$D$11*(1+$A8)*(הנחות!$C$36+הנחות!$C$39+הנחות!$C$43+הנחות!$C$45)+עלויות!$D$11*(1+$A8)*הנחות!$C$40*הנחות!$C$41+סיכום!$C$7*(1+H$4)*(הנחות!$C$37+הנחות!$C$38)+סיכום!$C$6*(1+H$4)*הנחות!$C$44+עלויות!$D$21+עלויות!$D$25+עלויות!$D$26)))/(עלויות!$D$37+עלויות!$D$11*(1+$A8)+(עלויות!$D$15+עלויות!$D$11*(1+$A8)*(הנחות!$C$36+הנחות!$C$39+הנחות!$C$43+הנחות!$C$45)+עלויות!$D$11*(1+$A8)*הנחות!$C$40*הנחות!$C$41+סיכום!$C$7*(1+H$4)*(הנחות!$C$37+הנחות!$C$38)+סיכום!$C$6*(1+H$4)*הנחות!$C$44+עלויות!$D$21+עלויות!$D$25+עלויות!$D$26)),0) -> 0.26533065 | I8: =IFERROR((סיכום!$C$7*(1+I$4)-(עלויות!$D$37+עלויות!$D$11*(1+$A8)+(עלויות!$D$15+עלויות!$D$11*(1+$A8)*(הנחות!$C$36+הנחות!$C$39+הנחות!$C$43+הנחות!$C$45)+עלויות!$D$11*(1+$A8)*הנחות!$C$40*הנחות!$C$41+סיכום!$C$7*(1+I$4)*(הנחות!$C$37+הנחות!$C$38)+סיכום!$C$6*(1+I$4)*הנחות!$C$44+עלויות!$D$21+עלויות!$D$25+עלויות!$D$26)))/(עלויות!$D$37+עלויות!$D$11*(1+$A8)+(עלויות!$D$15+עלויות!$D$11*(1+$A8)*(הנחות!$C$36+הנחות!$C$39+הנחות!$C$43+הנחות!$C$45)+עלויות!$D$11*(1+$A8)*הנחות!$C$40*הנחות!$C$41+סיכום!$C$7*(1+I$4)*(הנחות!$C$37+הנחות!$C$38)+סיכום!$C$6*(1+I$4)*הנחות!$C$44+עלויות!$D$21+עלויות!$D$25+עלויות!$D$26)),0) -> 0.29392012 | J8: =IFERROR((סיכום!$C$7*(1+J$4)-(עלויות!$D$37+עלויות!$D$11*(1+$A8)+(עלויות!$D$15+עלויות!$D$11*(1+$A8)*(הנחות!$C$36+הנחות!$C$39+הנחות!$C$43+הנחות!$C$45)+עלויות!$D$11*(1+$A8)*הנחות!$C$40*הנחות!$C$41+סיכום!$C$7*(1+J$4)*(הנחות!$C$37+הנחות!$C$38)+סיכום!$C$6*(1+J$4)*הנחות!$C$44+עלויות!$D$21+עלויות!$D$25+עלויות!$D$26)))/(עלויות!$D$37+עלויות!$D$11*(1+$A8)+(עלויות!$D$15+עלויות!$D$11*(1+$A8)*(הנחות!$C$36+הנחות!$C$39+הנחות!$C$43+הנחות!$C$45)+עלויות!$D$11*(1+$A8)*הנחות!$C$40*הנחות!$C$41+סיכום!$C$7*(1+J$4)*(הנחות!$C$37+הנחות!$C$38)+סיכום!$C$6*(1+J$4)*הנחות!$C$44+עלויות!$D$21+עלויות!$D$25+עלויות!$D$26)),0) -> 0.32244182
